Workbook

Sheet 룰
A1: 1) 기본 룰 - 4인 반장전 - 25000점 시작, 30000점 반환 - 10-20 우마 - 적도라, 깡도라, 뒷도라 있음, 쿠이탕 있음 - 더블리치 있음 - 셈 역만 인정 - 형식 텐파이(역 없는 텐파이) 허용 - 유국 시 연장 유지 - 들통(토비) 있음 - 동점자 발생 시 첫 친에 가까운 자리 순서대로 순위 결정 - 서입 있음 - 화료 중지(오라스 친이 화료 시 대국 종료 여부 선택) 불가 - 더블론시 방총자에서 가까운 사람이 리치봉 획득 - 기타 사정으로 남4국이 끝나기전의 종료 시 기록에서 제외 - 깡이후 신도라표시패 오픈은 안깡(암깡) = 즉시 / 명깡 = 타패 이후 (2020 / 08 / 08 추가) - 리치, 치, 뻥(언제든 가능) / 깡(패산에 쯔모할 패가 1개 이상일 때 가능) - 벌점 : 잘못된 발성(치,펑,깡) 시에만 적용 - 화료불가 : 잘못된 발성(리치, 론, 쯔모) 시에만 적용 - 도중유국 : 친의 노텐을 제외하고 친이 넘어가지 않음
A2: 2) 로컬(?) 룰 - 더블 론 있음(트리플 론 가능) - 2025.05.08 개정 - 팔연장 인정 - 5연장 이상 2판 묶기 있음 - 책임지불 있음(대삼원, 대사희, 사깡즈) - 사암각, 국사무쌍, 구련보등의 더블역만 조건 있음. 대사희(더블역만)
A3: 3) FAQ - 친의 촌보는 친이 넘어가지 않음 - 자가 촌보를 한 경우 해당 국을 취소하고 다시 진행 (해당 국의 벌점 및 리치 공탁금은 해당 대국자에게 반환) - 자의 유국만관 발생 시 친의 텐파이 여부 상관 없이 친이 넘어감 - 창깡 시의 깡도라는 인정하지 않음 - 네 번째 깡을 친 대국자가 영상패를 가져오고 타패한 후, 타가의 론이 없으면 4깡유국 발생 - 실수로 왕패 중에서 다른 패를 뒤집었을 경우, 실수로 뒤집은 패를 보이지 않게 제자리에 돌려놓고 다시 정규 표시패를 뒤집어 도라 표시패로 한다.
A4: - 촌보 : 모든 패를 합쳐 5개 이상 공개시, 론 쯔모 발성 후 패 공개하였을때 대기 패가 아니였을경우, 리치 후 유국되었을경우 텐파이 공개시 텐파이가 아닐 경우
A6: 참고 : https://kml.or.kr/?page_id=62&uid=945&mod=document&pageid=1

Sheet 플레이어
A1: 조연
A2: 댕댕
A3: 고꿍
A4: 절미
A5: 루젼
A6: 넥닉수
A7: 레이
A8: 한토
A9: 막장
A10: 나방
A11: 라비
A12: 서림
... A33: 또또

Sheet 입력
C1: 라운드 | D1: 254 | E1: <- 라운드입력 | H1: 화료
B2: 위치 | C2: 플레이어 | D2: 점수 | E2: 순위 | F2: 최종점수 | H2: 만관 | I2: 하네만 | J2: 배만 | K2: 삼배만 | L2: 역만 | M2: 헤아림 역만 | N2: 더블 역만
B3: 동 | E3: =RANK(D3, $D$3:$D$6) + COUNTIFS($D$3:D3, D3) - 1 -> #N/A | F3: =(D3-30000)/1000 + IFS(E3=1, 40, E3=2, 10, E3=3, -10, E3=4, -20) -> #N/A
B4: 남 | E4: =RANK(D4, $D$3:$D$6) + COUNTIFS($D$3:D4, D4) - 1 -> #N/A | F4: =(D4-30000)/1000 + IFS(E4=1, 40, E4=2, 10, E4=3, -10, E4=4, -20) -> #N/A
B5: 서 | E5: =RANK(D5, $D$3:$D$6) + COUNTIFS($D$3:D5, D5) - 1 -> #N/A | F5: =(D5-30000)/1000 + IFS(E5=1, 40, E5=2, 10, E5=3, -10, E5=4, -20) -> #N/A
B6: 북 | E6: =RANK(D6, $D$3:$D$6) + COUNTIFS($D$3:D6, D6) - 1 -> #N/A | F6: =(D6-30000)/1000 + IFS(E6=1, 40, E6=2, 10, E6=3, -10, E6=4, -20) -> #N/A
A7: 기록 저장 | D7: =sum(D3:D6) -> 0
A8: FALSE

Sheet 기록
A1: 날짜 | B1: 라운드 | C1: 바람 | D1: 이름 | E1: 최종점수 | F1: 순위 | G1: 우마 | I1: 만관 | J1: 하네만 | K1: 배만 | L1: 삼배만 | M1: 역만 | N1: 헤아림 역만 | O1: 더블 역만
A2: 46075.943 | B2: 253 | C2: 동 | D2: 라비 | E2: 35500 | F2: 2 | G2: 15.5 | I2: 1 | J2: 0 | K2: 0 | L2: 0 | M2: 0 | N2: 0 | O2: 0
A3: 46075.943 | B3: 253 | C3: 남 | D3: 댕댕 | E3: 18100 | F3: 3 | G3: -21.9 | I3: 0 | J3: 0 | K3: 0 | L3: 0 | M3: 0 | N3: 0 | O3: 0
A4: 46075.943 | B4: 253 | C4: 서 | D4: 절미 | E4: 52100 | F4: 1 | G4: 62.1 | I4: 3 | J4: 1 | K4: 0 | L4: 0 | M4: 0 | N4: 0 | O4: 0
A5: 46075.943 | B5: 253 | C5: 북 | D5: 물냉 | E5: -5700 | F5: 4 | G5: -55.7 | I5: 0 | J5: 0 | K5: 0 | L5: 0 | M5: 0 | N5: 0 | O5: 0
A6: 46075.886 | B6: 252 | C6: 동 | D6: 절미 | E6: 5700 | F6: 4 | G6: -44.3 | I6: 0 | J6: 0 | K6: 0 | L6: 0 | M6: 0 | N6: 0 | O6: 0
A7: 46075.886 | B7: 252 | C7: 남 | D7: 라비 | E7: 37900 | F7: 1 | G7: 47.9 | I7: 0 | J7: 0 | K7: 0 | L7: 0 | M7: 0 | N7: 0 | O7: 0
A8: 46075.886 | B8: 252 | C8: 서 | D8: 물냉 | E8: 28200 | F8: 2 | G8: 8.2 | I8: 0 | J8: 0 | K8: 0 | L8: 0 | M8: 0 | N8: 0 | O8: 0
A9: 46075.886 | B9: 252 | C9: 북 | D9: 댕댕 | E9: 28200 | F9: 3 | G9: -11.8 | I9: 0 | J9: 0 | K9: 0 | L9: 0 | M9: 0 | N9: 0 | O9: 0
A10: 46075.848 | B10: 251 | C10: 동 | D10: 댕댕 | E10: 25400 | F10: 2 | G10: 5.4 | I10: 0 | J10: 0 | K10: 0 | L10: 0 | M10: 0 | N10: 0 | O10: 0
A11: 46075.848 | B11: 251 | C11: 남 | D11: 절미 | E11: 56000 | F11: 1 | G11: 66 | I11: 1 | J11: 1 | K11: 0 | L11: 0 | M11: 0 | N11: 0 | O11: 0
A12: 46075.848 | B12: 251 | C12: 서 | D12: 라비 | E12: 15400 | F12: 3 | G12: -24.6 | I12: 0 | J12: 0 | K12: 0 | L12: 0 | M12: 0 | N12: 0 | O12: 0
A13: 46075.848 | B13: 251 | C13: 북 | D13: 물냉 | E13: 3200 | F13: 4 | G13: -46.8 | I13: 0 | J13: 0 | K13: 0 | L13: 0 | M13: 0 | N13: 0 | O13: 0
... A553: 45989.858 | B553: 110 | C553: 북 | D553: 댕댕 | E553: 54600 | F553: 1 | G553: 64.6 | I553: 0 | J553: 1 | K553: 0 | L553: 0 | M553: 0 | N553: 0 | O553: 0
A554: 45986.065 | B554: 109 | C554: 동 | D554: 루젼 | E554: 19700 | F554: 2 | G554: -0.3 | I554: 7 | J554: 3 | K554: 1 | L554: 0 | M554: 1
A555: 45986.065 | B555: 109 | C555: 남 | D555: 댕댕 | E555: 68200 | F555: 1 | G555: 78.2
A556: 45986.065 | B556: 109 | C556: 서 | D556: 막장 | E556: 16100 | F556: 3 | G556: -23.9
A557: 45986.065 | B557: 109 | C557: 북 | D557: 고꿍 | E557: -4000 | F557: 4 | G557: -54 | I557: 8 | J557: 4 | K557: 1 | L557: 0 | M557: 1
A558: 45986.064 | B558: 108 | C558: 동 | D558: 절미 | E558: 45900 | F558: 1 | G558: 55.9
A559: 45986.064 | B559: 108 | C559: 남 | D559: 블루 | E559: -2000 | F559: 4 | G559: -52
A560: 45986.064 | B560: 108 | C560: 서 | D560: 레이 | E560: 28100 | F560: 2 | G560: 8.1 | I560: 3
A561: 45986.064 | B561: 108 | C561: 북 | D561: 라비 | E561: 28000 | F561: 3 | G561: -12
A562: 45986.064 | B562: 107 | C562: 동 | D562: 절미 | E562: 30000 | F562: 3 | G562: -10
A563: 45986.064 | B563: 107 | C563: 남 | D563: 블루 | E563: 34200 | F563: 2 | G563: 14.2
A564: 45986.064 | B564: 107 | C564: 서 | D564: 막장 | E564: -6800 | F564: 4 | G564: -56.8
A565: 45986.064 | B565: 107 | C565: 북 | D565: 루젼 | E565: 42600 | F565: 1 | G565: 52.6
A566: 45986.064 | B566: 106 | C566: 동 | D566: 고꿍 | E566: 31900 | F566: 2 | G566: 11.9
A567: 45986.064 | B567: 106 | C567: 남 | D567: 레이 | E567: 2000 | F567: 4 | G567: -48
A568: 45986.064 | B568: 106 | C568: 서 | D568: 라비 | E568: 22500 | F568: 3 | G568: -17.5
A569: 45986.064 | B569: 106 | C569: 북 | D569: 댕댕 | E569: 43600 | F569: 1 | G569: 53.6
A570: 45986.064 | B570: 105 | C570: 동 | D570: 이비 | E570: -25600 | F570: 4 | G570: -75.6
A571: 45986.064 | B571: 105 | C571: 남 | D571: 댕댕 | E571: 22600 | F571: 3 | G571: -17.4
A572: 45986.064 | B572: 105 | C572: 서 | D572: 루젼 | E572: 47100 | F572: 2 | G572: 27.1
... A578: 45986.063 | B578: 103 | C578: 동 | D578: 루젼 | E578: 21500 | F578: 3 | G578: -18.5
A579: 45986.063 | B579: 103 | C579: 남 | D579: 이비 | E579: 26100 | F579: 2 | G579: 6.1 | I579: 1
A580: 45986.063 | B580: 103 | C580: 서 | D580: 고꿍 | E580: 41400 | F580: 1 | G580: 51.4
A581: 45986.063 | B581: 103 | C581: 북 | D581: 댕댕 | E581: 11000 | F581: 4 | G581: -39
A582: 45986.063 | B582: 102 | C582: 동 | D582: 라비 | E582: 31100 | F582: 2 | G582: 11.1
A583: 45986.063 | B583: 102 | C583: 남 | D583: 댕댕 | E583: 18900 | F583: 3 | G583: -21.1
A584: 45986.063 | B584: 102 | C584: 서 | D584: 이비 | E584: 35300 | F584: 1 | G584: 45.3
...

Sheet 통계
A1: 시즌 | C1: 동 | D1: 남 | E1: 서 | F1: 북
A2: 2026 | B2: 평균순위 | C2: =IFERROR(AVERAGEIF('기록'!$C:$C, $C$1, '기록'!$F:$F), "-") -> 2.5163934 | D2: =IFERROR(AVERAGEIF('기록'!$C:$C, $D$1, '기록'!$F:$F), "-") -> 2.5040984 | E2: =IFERROR(AVERAGEIF('기록'!$C:$C, $E$1, '기록'!$F:$F), "-") -> 2.4385246 | F2: =IFERROR(AVERAGEIF('기록'!$C:$C, $F$1, '기록'!$F:$F), "-") -> 2.5409836
B3: 평균우마 | C3: =IFERROR(AVERAGEIF('기록'!$C:$C, $C$1, '기록'!$G:$G), "-") -> -0.8954918 | D3: =IFERROR(AVERAGEIF('기록'!$C:$C, $D$1, '기록'!$G:$G), "-") -> 0.90245902 | E3: =IFERROR(AVERAGEIF('기록'!$C:$C, $E$1, '기록'!$G:$G), "-") -> 1.8233607 | F3: =IFERROR(AVERAGEIF('기록'!$C:$C, $F$1, '기록'!$G:$G), "-") -> -1.8303279
B4: 총 우마 | C4: =SUMIF('기록'!$C:$C, $C$1, '기록'!$G:$G) -> -218.5 | D4: =SUMIF('기록'!$C:$C, $D$1, '기록'!$G:$G) -> 220.2 | E4: =SUMIF('기록'!$C:$C, $E$1, '기록'!$G:$G) -> 444.9 | F4: =SUMIF('기록'!$C:$C, $F$1, '기록'!$G:$G) -> -446.6
C6: {=TRANSPOSE('플레이어'!A1:A1007)} -> 조연 | D6: 댕댕 | E6: 고꿍 | F6: 절미 | G6: 루젼 | H6: 넥닉수 | I6: 레이 | J6: 한토 | K6: 막장 | L6: 나방 | M6: 라비 | N6: 서림 | O6: 밍밍 | P6: 게스트 | Q6: 호또 | R6: 으나 | S6: 이비 | T6: 블루 | U6: 아초 | V6: 노세 | W6: 달달 | X6: 코니 | Y6: 춘식 | Z6: 누리 | AA6: 식빵 | AB6: 카롱 | AC6: 쇼 | AD6: 촌장 | AE6: 추워 | AF6: 채또 | AG6: 물냉 | AH6: DM | AI6: 또또
A7: 총 누적 경기수 | B7: 총 경기수 | C7: =IFERROR(__xludf.DUMMYFUNCTION("IF(C$6="""", """", IFERROR(ROWS(FILTER('기록'!$A:$A, ('기록'!$D:$D=C$6) * (IF($A$2=""전체"", TRUE, (YEAR('기록'!$A:$A)&"""")=$A$2)))), 0))"),20.0) -> 20 | D7: =IFERROR(__xludf.DUMMYFUNCTION("IF(D$6="""", """", IFERROR(ROWS(FILTER('기록'!$A:$A, ('기록'!$D:$D=D$6) * (IF($A$2=""전체"", TRUE, (YEAR('기록'!$A:$A)&"""")=$A$2)))), 0))"),48.0) -> 48 | E7: =IFERROR(__xludf.DUMMYFUNCTION("IF(E$6="""", """", IFERROR(ROWS(FILTER('기록'!$A:$A, ('기록'!$D:$D=E$6) * (IF($A$2=""전체"", TRUE, (YEAR('기록'!$A:$A)&"""")=$A$2)))), 0))"),19.0) -> 19 | F7: =IFERROR(__xludf.DUMMYFUNCTION("IF(F$6="""", """", IFERROR(ROWS(FILTER('기록'!$A:$A, ('기록'!$D:$D=F$6) * (IF($A$2=""전체"", TRUE, (YEAR('기록'!$A:$A)&"""")=$A$2)))), 0))"),28.0) -> 28 | G7: =IFERROR(__xludf.DUMMYFUNCTION("IF(G$6="""", """", IFERROR(ROWS(FILTER('기록'!$A:$A, ('기록'!$D:$D=G$6) * (IF($A$2=""전체"", TRUE, (YEAR('기록'!$A:$A)&"""")=$A$2)))), 0))"),19.0) -> 19 | H7: =IFERROR(__xludf.DUMMYFUNCTION("IF(H$6="""", """", IFERROR(ROWS(FILTER('기록'!$A:$A, ('기록'!$D:$D=H$6) * (IF($A$2=""전체"", TRUE, (YEAR('기록'!$A:$A)&"""")=$A$2)))), 0))"),10.0) -> 10 | I7: =IFERROR(__xludf.DUMMYFUNCTION("IF(I$6="""", """", IFERROR(ROWS(FILTER('기록'!$A:$A, ('기록'!$D:$D=I$6) * (IF($A$2=""전체"", TRUE, (YEAR('기록'!$A:$A)&"""")=$A$2)))), 0))"),7.0) -> 7 | J7: =IFERROR(__xludf.DUMMYFUNCTION("IF(J$6="""", """", IFERROR(ROWS(FILTER('기록'!$A:$A, ('기록'!$D:$D=J$6) * (IF($A$2=""전체"", TRUE, (YEAR('기록'!$A:$A)&"""")=$A$2)))), 0))"),0.0) -> 0 | K7: =IFERROR(__xludf.DUMMYFUNCTION("IF(K$6="""", """", IFERROR(ROWS(FILTER('기록'!$A:$A, ('기록'!$D:$D=K$6) * (IF($A$2=""전체"", TRUE, (YEAR('기록'!$A:$A)&"""")=$A$2)))), 0))"),7.0) -> 7 | L7: =IFERROR(__xludf.DUMMYFUNCTION("IF(L$6="""", """", IFERROR(ROWS(FILTER('기록'!$A:$A, ('기록'!$D:$D=L$6) * (IF($A$2=""전체"", TRUE, (YEAR('기록'!$A:$A)&"""")=$A$2)))), 0))"),17.0) -> 17 | M7: =IFERROR(__xludf.DUMMYFUNCTION("IF(M$6="""", """", IFERROR(ROWS(FILTER('기록'!$A:$A, ('기록'!$D:$D=M$6) * (IF($A$2=""전체"", TRUE, (YEAR('기록'!$A:$A)&"""")=$A$2)))), 0))"),37.0) -> 37 | N7: =IFERROR(__xludf.DUMMYFUNCTION("IF(N$6="""", """", IFERROR(ROWS(FILTER('기록'!$A:$A, ('기록'!$D:$D=N$6) * (IF($A$2=""전체"", TRUE, (YEAR('기록'!$A:$A)&"""")=$A$2)))), 0))"),0.0) -> 0 | O7: =IFERROR(__xludf.DUMMYFUNCTION("IF(O$6="""", """", IFERROR(ROWS(FILTER('기록'!$A:$A, ('기록'!$D:$D=O$6) * (IF($A$2=""전체"", TRUE, (YEAR('기록'!$A:$A)&"""")=$A$2)))), 0))"),5.0) -> 5 | P7: =IFERROR(__xludf.DUMMYFUNCTION("IF(P$6="""", """", IFERROR(ROWS(FILTER('기록'!$A:$A, ('기록'!$D:$D=P$6) * (IF($A$2=""전체"", TRUE, (YEAR('기록'!$A:$A)&"""")=$A$2)))), 0))"),0.0) -> 0 | Q7: =IFERROR(__xludf.DUMMYFUNCTION("IF(Q$6="""", """", IFERROR(ROWS(FILTER('기록'!$A:$A, ('기록'!$D:$D=Q$6) * (IF($A$2=""전체"", TRUE, (YEAR('기록'!$A:$A)&"""")=$A$2)))), 0))"),0.0) -> 0 | R7: =IFERROR(__xludf.DUMMYFUNCTION("IF(R$6="""", """", IFERROR(ROWS(FILTER('기록'!$A:$A, ('기록'!$D:$D=R$6) * (IF($A$2=""전체"", TRUE, (YEAR('기록'!$A:$A)&"""")=$A$2)))), 0))"),0.0) -> 0 | S7: =IFERROR(__xludf.DUMMYFUNCTION("IF(S$6="""", """", IFERROR(ROWS(FILTER('기록'!$A:$A, ('기록'!$D:$D=S$6) * (IF($A$2=""전체"", TRUE, (YEAR('기록'!$A:$A)&"""")=$A$2)))), 0))"),0.0) -> 0 | T7: =IFERROR(__xludf.DUMMYFUNCTION("IF(T$6="""", """", IFERROR(ROWS(FILTER('기록'!$A:$A, ('기록'!$D:$D=T$6) * (IF($A$2=""전체"", TRUE, (YEAR('기록'!$A:$A)&"""")=$A$2)))), 0))"),0.0) -> 0 | U7: =IFERROR(__xludf.DUMMYFUNCTION("IF(U$6="""", """", IFERROR(ROWS(FILTER('기록'!$A:$A, ('기록'!$D:$D=U$6) * (IF($A$2=""전체"", TRUE, (YEAR('기록'!$A:$A)&"""")=$A$2)))), 0))"),0.0) -> 0 | V7: =IFERROR(__xludf.DUMMYFUNCTION("IF(V$6="""", """", IFERROR(ROWS(FILTER('기록'!$A:$A, ('기록'!$D:$D=V$6) * (IF($A$2=""전체"", TRUE, (YEAR('기록'!$A:$A)&"""")=$A$2)))), 0))"),12.0) -> 12 | W7: =IFERROR(__xludf.DUMMYFUNCTION("IF(W$6="""", """", IFERROR(ROWS(FILTER('기록'!$A:$A, ('기록'!$D:$D=W$6) * (IF($A$2=""전체"", TRUE, (YEAR('기록'!$A:$A)&"""")=$A$2)))), 0))"),0.0) -> 0 | X7: =IFERROR(__xludf.DUMMYFUNCTION("IF(X$6="""", """", IFERROR(ROWS(FILTER('기록'!$A:$A, ('기록'!$D:$D=X$6) * (IF($A$2=""전체"", TRUE, (YEAR('기록'!$A:$A)&"""")=$A$2)))), 0))"),0.0) -> 0 | Y7: =IFERROR(__xludf.DUMMYFUNCTION("IF(Y$6="""", """", IFERROR(ROWS(FILTER('기록'!$A:$A, ('기록'!$D:$D=Y$6) * (IF($A$2=""전체"", TRUE, (YEAR('기록'!$A:$A)&"""")=$A$2)))), 0))"),0.0) -> 0 | Z7: =IFERROR(__xludf.DUMMYFUNCTION("IF(Z$6="""", """", IFERROR(ROWS(FILTER('기록'!$A:$A, ('기록'!$D:$D=Z$6) * (IF($A$2=""전체"", TRUE, (YEAR('기록'!$A:$A)&"""")=$A$2)))), 0))"),0.0) -> 0 | AA7: =IFERROR(__xludf.DUMMYFUNCTION("IF(AA$6="""", """", IFERROR(ROWS(FILTER('기록'!$A:$A, ('기록'!$D:$D=AA$6) * (IF($A$2=""전체"", TRUE, (YEAR('기록'!$A:$A)&"""")=$A$2)))), 0))"),0.0) -> 0 | AB7: =IFERROR(__xludf.DUMMYFUNCTION("IF(AB$6="""", """", IFERROR(ROWS(FILTER('기록'!$A:$A, ('기록'!$D:$D=AB$6) * (IF($A$2=""전체"", TRUE, (YEAR('기록'!$A:$A)&"""")=$A$2)))), 0))"),0.0) -> 0 | AC7: =IFERROR(__xludf.DUMMYFUNCTION("IF(AC$6="""", """", IFERROR(ROWS(FILTER('기록'!$A:$A, ('기록'!$D:$D=AC$6) * (IF($A$2=""전체"", TRUE, (YEAR('기록'!$A:$A)&"""")=$A$2)))), 0))"),9.0) -> 9 | AD7: =IFERROR(__xludf.DUMMYFUNCTION("IF(AD$6="""", """", IFERROR(ROWS(FILTER('기록'!$A:$A, ('기록'!$D:$D=AD$6) * (IF($A$2=""전체"", TRUE, (YEAR('기록'!$A:$A)&"""")=$A$2)))), 0))"),0.0) -> 0 | AE7: =IFERROR(__xludf.DUMMYFUNCTION("IF(AE$6="""", """", IFERROR(ROWS(FILTER('기록'!$A:$A, ('기록'!$D:$D=AE$6) * (IF($A$2=""전체"", TRUE, (YEAR('기록'!$A:$A)&"""")=$A$2)))), 0))"),0.0) -> 0 | AF7: =IFERROR(__xludf.DUMMYFUNCTION("IF(AF$6="""", """", IFERROR(ROWS(FILTER('기록'!$A:$A, ('기록'!$D:$D=AF$6) * (IF($A$2=""전체"", TRUE, (YEAR('기록'!$A:$A)&"""")=$A$2)))), 0))"),0.0) -> 0 | AG7: =IFERROR(__xludf.DUMMYFUNCTION("IF(AG$6="""", """", IFERROR(ROWS(FILTER('기록'!$A:$A, ('기록'!$D:$D=AG$6) * (IF($A$2=""전체"", TRUE, (YEAR('기록'!$A:$A)&"""")=$A$2)))), 0))"),8.0) -> 8 | AH7: =IFERROR(__xludf.DUMMYFUNCTION("IF(AH$6="""", """", IFERROR(ROWS(FILTER('기록'!$A:$A, ('기록'!$D:$D=AH$6) * (IF($A$2=""전체"", TRUE, (YEAR('기록'!$A:$A)&"""")=$A$2)))), 0))"),12.0) -> 12 | AI7: =IFERROR(__xludf.DUMMYFUNCTION("IF(AI$6="""", """", IFERROR(ROWS(FILTER('기록'!$A:$A, ('기록'!$D:$D=AI$6) * (IF($A$2=""전체"", TRUE, (YEAR('기록'!$A:$A)&"""")=$A$2)))), 0))"),6.0) -> 6
A8: =MAX('기록'!B:B) -> 253 | B8: 1위율 | C8: =IFERROR(__xludf.DUMMYFUNCTION("IF(C$6="""", """", IFERROR(ROWS(FILTER('기록'!$F:$F, ('기록'!$D:$D=C$6) * ('기록'!$F:$F=1) * (IF($A$2=""전체"", TRUE, (YEAR('기록'!$A:$A)&"""")=$A$2)))) / C$7, ""-""))"),0.2) -> 0.2 | D8: =IFERROR(__xludf.DUMMYFUNCTION("IF(D$6="""", """", IFERROR(ROWS(FILTER('기록'!$F:$F, ('기록'!$D:$D=D$6) * ('기록'!$F:$F=1) * (IF($A$2=""전체"", TRUE, (YEAR('기록'!$A:$A)&"""")=$A$2)))) / D$7, ""-""))"),0.3333333333333333) -> 0.33333333 | E8: =IFERROR(__xludf.DUMMYFUNCTION("IF(E$6="""", """", IFERROR(ROWS(FILTER('기록'!$F:$F, ('기록'!$D:$D=E$6) * ('기록'!$F:$F=1) * (IF($A$2=""전체"", TRUE, (YEAR('기록'!$A:$A)&"""")=$A$2)))) / E$7, ""-""))"),0.2631578947368421) -> 0.26315789 | F8: =IFERROR(__xludf.DUMMYFUNCTION("IF(F$6="""", """", IFERROR(ROWS(FILTER('기록'!$F:$F, ('기록'!$D:$D=F$6) * ('기록'!$F:$F=1) * (IF($A$2=""전체"", TRUE, (YEAR('기록'!$A:$A)&"""")=$A$2)))) / F$7, ""-""))"),0.17857142857142858) -> 0.17857143 | G8: =IFERROR(__xludf.DUMMYFUNCTION("IF(G$6="""", """", IFERROR(ROWS(FILTER('기록'!$F:$F, ('기록'!$D:$D=G$6) * ('기록'!$F:$F=1) * (IF($A$2=""전체"", TRUE, (YEAR('기록'!$A:$A)&"""")=$A$2)))) / G$7, ""-""))"),0.10526315789473684) -> 0.10526316 | H8: =IFERROR(__xludf.DUMMYFUNCTION("IF(H$6="""", """", IFERROR(ROWS(FILTER('기록'!$F:$F, ('기록'!$D:$D=H$6) * ('기록'!$F:$F=1) * (IF($A$2=""전체"", TRUE, (YEAR('기록'!$A:$A)&"""")=$A$2)))) / H$7, ""-""))"),0.2) -> 0.2 | I8: =IFERROR(__xludf.DUMMYFUNCTION("IF(I$6="""", """", IFERROR(ROWS(FILTER('기록'!$F:$F, ('기록'!$D:$D=I$6) * ('기록'!$F:$F=1) * (IF($A$2=""전체"", TRUE, (YEAR('기록'!$A:$A)&"""")=$A$2)))) / I$7, ""-""))"),0.42857142857142855) -> 0.42857143 | J8: =IFERROR(__xludf.DUMMYFUNCTION("IF(J$6="""", """", IFERROR(ROWS(FILTER('기록'!$F:$F, ('기록'!$D:$D=J$6) * ('기록'!$F:$F=1) * (IF($A$2=""전체"", TRUE, (YEAR('기록'!$A:$A)&"""")=$A$2)))) / J$7, ""-""))"),"-") -> - | K8: =IFERROR(__xludf.DUMMYFUNCTION("IF(K$6="""", """", IFERROR(ROWS(FILTER('기록'!$F:$F, ('기록'!$D:$D=K$6) * ('기록'!$F:$F=1) * (IF($A$2=""전체"", TRUE, (YEAR('기록'!$A:$A)&"""")=$A$2)))) / K$7, ""-""))"),0.2857142857142857) -> 0.28571429 | L8: =IFERROR(__xludf.DUMMYFUNCTION("IF(L$6="""", """", IFERROR(ROWS(FILTER('기록'!$F:$F, ('기록'!$D:$D=L$6) * ('기록'!$F:$F=1) * (IF($A$2=""전체"", TRUE, (YEAR('기록'!$A:$A)&"""")=$A$2)))) / L$7, ""-""))"),0.4117647058823529) -> 0.41176471 | M8: =IFERROR(__xludf.DUMMYFUNCTION("IF(M$6="""", """", IFERROR(ROWS(FILTER('기록'!$F:$F, ('기록'!$D:$D=M$6) * ('기록'!$F:$F=1) * (IF($A$2=""전체"", TRUE, (YEAR('기록'!$A:$A)&"""")=$A$2)))) / M$7, ""-""))"),0.35135135135135137) -> 0.35135135 | N8: =IFERROR(__xludf.DUMMYFUNCTION("IF(N$6="""", """", IFERROR(ROWS(FILTER('기록'!$F:$F, ('기록'!$D:$D=N$6) * ('기록'!$F:$F=1) * (IF($A$2=""전체"", TRUE, (YEAR('기록'!$A:$A)&"""")=$A$2)))) / N$7, ""-""))"),"-") -> - | O8: =IFERROR(__xludf.DUMMYFUNCTION("IF(O$6="""", """", IFERROR(ROWS(FILTER('기록'!$F:$F, ('기록'!$D:$D=O$6) * ('기록'!$F:$F=1) * (IF($A$2=""전체"", TRUE, (YEAR('기록'!$A:$A)&"""")=$A$2)))) / O$7, ""-""))"),"-") -> - | P8: =IFERROR(__xludf.DUMMYFUNCTION("IF(P$6="""", """", IFERROR(ROWS(FILTER('기록'!$F:$F, ('기록'!$D:$D=P$6) * ('기록'!$F:$F=1) * (IF($A$2=""전체"", TRUE, (YEAR('기록'!$A:$A)&"""")=$A$2)))) / P$7, ""-""))"),"-") -> - | Q8: =IFERROR(__xludf.DUMMYFUNCTION("IF(Q$6="""", """", IFERROR(ROWS(FILTER('기록'!$F:$F, ('기록'!$D:$D=Q$6) * ('기록'!$F:$F=1) * (IF($A$2=""전체"", TRUE, (YEAR('기록'!$A:$A)&"""")=$A$2)))) / Q$7, ""-""))"),"-") -> - | R8: =IFERROR(__xludf.DUMMYFUNCTION("IF(R$6="""", """", IFERROR(ROWS(FILTER('기록'!$F:$F, ('기록'!$D:$D=R$6) * ('기록'!$F:$F=1) * (IF($A$2=""전체"", TRUE, (YEAR('기록'!$A:$A)&"""")=$A$2)))) / R$7, ""-""))"),"-") -> - | S8: =IFERROR(__xludf.DUMMYFUNCTION("IF(S$6="""", """", IFERROR(ROWS(FILTER('기록'!$F:$F, ('기록'!$D:$D=S$6) * ('기록'!$F:$F=1) * (IF($A$2=""전체"", TRUE, (YEAR('기록'!$A:$A)&"""")=$A$2)))) / S$7, ""-""))"),"-") -> - | T8: =IFERROR(__xludf.DUMMYFUNCTION("IF(T$6="""", """", IFERROR(ROWS(FILTER('기록'!$F:$F, ('기록'!$D:$D=T$6) * ('기록'!$F:$F=1) * (IF($A$2=""전체"", TRUE, (YEAR('기록'!$A:$A)&"""")=$A$2)))) / T$7, ""-""))"),"-") -> - | U8: =IFERROR(__xludf.DUMMYFUNCTION("IF(U$6="""", """", IFERROR(ROWS(FILTER('기록'!$F:$F, ('기록'!$D:$D=U$6) * ('기록'!$F:$F=1) * (IF($A$2=""전체"", TRUE, (YEAR('기록'!$A:$A)&"""")=$A$2)))) / U$7, ""-""))"),"-") -> - | V8: =IFERROR(__xludf.DUMMYFUNCTION("IF(V$6="""", """", IFERROR(ROWS(FILTER('기록'!$F:$F, ('기록'!$D:$D=V$6) * ('기록'!$F:$F=1) * (IF($A$2=""전체"", TRUE, (YEAR('기록'!$A:$A)&"""")=$A$2)))) / V$7, ""-""))"),0.16666666666666666) -> 0.16666667 | W8: =IFERROR(__xludf.DUMMYFUNCTION("IF(W$6="""", """", IFERROR(ROWS(FILTER('기록'!$F:$F, ('기록'!$D:$D=W$6) * ('기록'!$F:$F=1) * (IF($A$2=""전체"", TRUE, (YEAR('기록'!$A:$A)&"""")=$A$2)))) / W$7, ""-""))"),"-") -> - | X8: =IFERROR(__xludf.DUMMYFUNCTION("IF(X$6="""", """", IFERROR(ROWS(FILTER('기록'!$F:$F, ('기록'!$D:$D=X$6) * ('기록'!$F:$F=1) * (IF($A$2=""전체"", TRUE, (YEAR('기록'!$A:$A)&"""")=$A$2)))) / X$7, ""-""))"),"-") -> - | Y8: =IFERROR(__xludf.DUMMYFUNCTION("IF(Y$6="""", """", IFERROR(ROWS(FILTER('기록'!$F:$F, ('기록'!$D:$D=Y$6) * ('기록'!$F:$F=1) * (IF($A$2=""전체"", TRUE, (YEAR('기록'!$A:$A)&"""")=$A$2)))) / Y$7, ""-""))"),"-") -> - | Z8: =IFERROR(__xludf.DUMMYFUNCTION("IF(Z$6="""", """", IFERROR(ROWS(FILTER('기록'!$F:$F, ('기록'!$D:$D=Z$6) * ('기록'!$F:$F=1) * (IF($A$2=""전체"", TRUE, (YEAR('기록'!$A:$A)&"""")=$A$2)))) / Z$7, ""-""))"),"-") -> - | AA8: =IFERROR(__xludf.DUMMYFUNCTION("IF(AA$6="""", """", IFERROR(ROWS(FILTER('기록'!$F:$F, ('기록'!$D:$D=AA$6) * ('기록'!$F:$F=1) * (IF($A$2=""전체"", TRUE, (YEAR('기록'!$A:$A)&"""")=$A$2)))) / AA$7, ""-""))"),"-") -> - | AB8: =IFERROR(__xludf.DUMMYFUNCTION("IF(AB$6="""", """", IFERROR(ROWS(FILTER('기록'!$F:$F, ('기록'!$D:$D=AB$6) * ('기록'!$F:$F=1) * (IF($A$2=""전체"", TRUE, (YEAR('기록'!$A:$A)&"""")=$A$2)))) / AB$7, ""-""))"),"-") -> - | AC8: =IFERROR(__xludf.DUMMYFUNCTION("IF(AC$6="""", """", IFERROR(ROWS(FILTER('기록'!$F:$F, ('기록'!$D:$D=AC$6) * ('기록'!$F:$F=1) * (IF($A$2=""전체"", TRUE, (YEAR('기록'!$A:$A)&"""")=$A$2)))) / AC$7, ""-""))"),"-") -> - | AD8: =IFERROR(__xludf.DUMMYFUNCTION("IF(AD$6="""", """", IFERROR(ROWS(FILTER('기록'!$F:$F, ('기록'!$D:$D=AD$6) * ('기록'!$F:$F=1) * (IF($A$2=""전체"", TRUE, (YEAR('기록'!$A:$A)&"""")=$A$2)))) / AD$7, ""-""))"),"-") -> - | AE8: =IFERROR(__xludf.DUMMYFUNCTION("IF(AE$6="""", """", IFERROR(ROWS(FILTER('기록'!$F:$F, ('기록'!$D:$D=AE$6) * ('기록'!$F:$F=1) * (IF($A$2=""전체"", TRUE, (YEAR('기록'!$A:$A)&"""")=$A$2)))) / AE$7, ""-""))"),"-") -> - | AF8: =IFERROR(__xludf.DUMMYFUNCTION("IF(AF$6="""", """", IFERROR(ROWS(FILTER('기록'!$F:$F, ('기록'!$D:$D=AF$6) * ('기록'!$F:$F=1) * (IF($A$2=""전체"", TRUE, (YEAR('기록'!$A:$A)&"""")=$A$2)))) / AF$7, ""-""))"),"-") -> - | AG8: =IFERROR(__xludf.DUMMYFUNCTION("IF(AG$6="""", """", IFERROR(ROWS(FILTER('기록'!$F:$F, ('기록'!$D:$D=AG$6) * ('기록'!$F:$F=1) * (IF($A$2=""전체"", TRUE, (YEAR('기록'!$A:$A)&"""")=$A$2)))) / AG$7, ""-""))"),0.25) -> 0.25 | AH8: =IFERROR(__xludf.DUMMYFUNCTION("IF(AH$6="""", """", IFERROR(ROWS(FILTER('기록'!$F:$F, ('기록'!$D:$D=AH$6) * ('기록'!$F:$F=1) * (IF($A$2=""전체"", TRUE, (YEAR('기록'!$A:$A)&"""")=$A$2)))) / AH$7, ""-""))"),0.08333333333333333) -> 0.083333333 | AI8: =IFERROR(__xludf.DUMMYFUNCTION("IF(AI$6="""", """", IFERROR(ROWS(FILTER('기록'!$F:$F, ('기록'!$D:$D=AI$6) * ('기록'!$F:$F=1) * (IF($A$2=""전체"", TRUE, (YEAR('기록'!$A:$A)&"""")=$A$2)))) / AI$7, ""-""))"),0.3333333333333333) -> 0.33333333
B9: 2위율 | C9: =IFERROR(__xludf.DUMMYFUNCTION("IF(C$6="""", """", IFERROR(ROWS(FILTER('기록'!$F:$F, ('기록'!$D:$D=C$6) * ('기록'!$F:$F=2) * (IF($A$2=""전체"", TRUE, (YEAR('기록'!$A:$A)&"""")=$A$2)))) / C$7, ""-""))"),0.35) -> 0.35 | D9: =IFERROR(__xludf.DUMMYFUNCTION("IF(D$6="""", """", IFERROR(ROWS(FILTER('기록'!$F:$F, ('기록'!$D:$D=D$6) * ('기록'!$F:$F=2) * (IF($A$2=""전체"", TRUE, (YEAR('기록'!$A:$A)&"""")=$A$2)))) / D$7, ""-""))"),0.25) -> 0.25 | E9: =IFERROR(__xludf.DUMMYFUNCTION("IF(E$6="""", """", IFERROR(ROWS(FILTER('기록'!$F:$F, ('기록'!$D:$D=E$6) * ('기록'!$F:$F=2) * (IF($A$2=""전체"", TRUE, (YEAR('기록'!$A:$A)&"""")=$A$2)))) / E$7, ""-""))"),0.21052631578947367) -> 0.21052632 | F9: =IFERROR(__xludf.DUMMYFUNCTION("IF(F$6="""", """", IFERROR(ROWS(FILTER('기록'!$F:$F, ('기록'!$D:$D=F$6) * ('기록'!$F:$F=2) * (IF($A$2=""전체"", TRUE, (YEAR('기록'!$A:$A)&"""")=$A$2)))) / F$7, ""-""))"),0.25) -> 0.25 | G9: =IFERROR(__xludf.DUMMYFUNCTION("IF(G$6="""", """", IFERROR(ROWS(FILTER('기록'!$F:$F, ('기록'!$D:$D=G$6) * ('기록'!$F:$F=2) * (IF($A$2=""전체"", TRUE, (YEAR('기록'!$A:$A)&"""")=$A$2)))) / G$7, ""-""))"),0.42105263157894735) -> 0.42105263 | H9: =IFERROR(__xludf.DUMMYFUNCTION("IF(H$6="""", """", IFERROR(ROWS(FILTER('기록'!$F:$F, ('기록'!$D:$D=H$6) * ('기록'!$F:$F=2) * (IF($A$2=""전체"", TRUE, (YEAR('기록'!$A:$A)&"""")=$A$2)))) / H$7, ""-""))"),0.2) -> 0.2 | I9: =IFERROR(__xludf.DUMMYFUNCTION("IF(I$6="""", """", IFERROR(ROWS(FILTER('기록'!$F:$F, ('기록'!$D:$D=I$6) * ('기록'!$F:$F=2) * (IF($A$2=""전체"", TRUE, (YEAR('기록'!$A:$A)&"""")=$A$2)))) / I$7, ""-""))"),"-") -> - | J9: =IFERROR(__xludf.DUMMYFUNCTION("IF(J$6="""", """", IFERROR(ROWS(FILTER('기록'!$F:$F, ('기록'!$D:$D=J$6) * ('기록'!$F:$F=2) * (IF($A$2=""전체"", TRUE, (YEAR('기록'!$A:$A)&"""")=$A$2)))) / J$7, ""-""))"),"-") -> - | K9: =IFERROR(__xludf.DUMMYFUNCTION("IF(K$6="""", """", IFERROR(ROWS(FILTER('기록'!$F:$F, ('기록'!$D:$D=K$6) * ('기록'!$F:$F=2) * (IF($A$2=""전체"", TRUE, (YEAR('기록'!$A:$A)&"""")=$A$2)))) / K$7, ""-""))"),0.2857142857142857) -> 0.28571429 | L9: =IFERROR(__xludf.DUMMYFUNCTION("IF(L$6="""", """", IFERROR(ROWS(FILTER('기록'!$F:$F, ('기록'!$D:$D=L$6) * ('기록'!$F:$F=2) * (IF($A$2=""전체"", TRUE, (YEAR('기록'!$A:$A)&"""")=$A$2)))) / L$7, ""-""))"),0.17647058823529413) -> 0.17647059 | M9: =IFERROR(__xludf.DUMMYFUNCTION("IF(M$6="""", """", IFERROR(ROWS(FILTER('기록'!$F:$F, ('기록'!$D:$D=M$6) * ('기록'!$F:$F=2) * (IF($A$2=""전체"", TRUE, (YEAR('기록'!$A:$A)&"""")=$A$2)))) / M$7, ""-""))"),0.24324324324324326) -> 0.24324324 | N9: =IFERROR(__xludf.DUMMYFUNCTION("IF(N$6="""", """", IFERROR(ROWS(FILTER('기록'!$F:$F, ('기록'!$D:$D=N$6) * ('기록'!$F:$F=2) * (IF($A$2=""전체"", TRUE, (YEAR('기록'!$A:$A)&"""")=$A$2)))) / N$7, ""-""))"),"-") -> - | O9: =IFERROR(__xludf.DUMMYFUNCTION("IF(O$6="""", """", IFERROR(ROWS(FILTER('기록'!$F:$F, ('기록'!$D:$D=O$6) * ('기록'!$F:$F=2) * (IF($A$2=""전체"", TRUE, (YEAR('기록'!$A:$A)&"""")=$A$2)))) / O$7, ""-""))"),0.2) -> 0.2 | P9: =IFERROR(__xludf.DUMMYFUNCTION("IF(P$6="""", """", IFERROR(ROWS(FILTER('기록'!$F:$F, ('기록'!$D:$D=P$6) * ('기록'!$F:$F=2) * (IF($A$2=""전체"", TRUE, (YEAR('기록'!$A:$A)&"""")=$A$2)))) / P$7, ""-""))"),"-") -> - | Q9: =IFERROR(__xludf.DUMMYFUNCTION("IF(Q$6="""", """", IFERROR(ROWS(FILTER('기록'!$F:$F, ('기록'!$D:$D=Q$6) * ('기록'!$F:$F=2) * (IF($A$2=""전체"", TRUE, (YEAR('기록'!$A:$A)&"""")=$A$2)))) / Q$7, ""-""))"),"-") -> - | R9: =IFERROR(__xludf.DUMMYFUNCTION("IF(R$6="""", """", IFERROR(ROWS(FILTER('기록'!$F:$F, ('기록'!$D:$D=R$6) * ('기록'!$F:$F=2) * (IF($A$2=""전체"", TRUE, (YEAR('기록'!$A:$A)&"""")=$A$2)))) / R$7, ""-""))"),"-") -> - | S9: =IFERROR(__xludf.DUMMYFUNCTION("IF(S$6="""", """", IFERROR(ROWS(FILTER('기록'!$F:$F, ('기록'!$D:$D=S$6) * ('기록'!$F:$F=2) * (IF($A$2=""전체"", TRUE, (YEAR('기록'!$A:$A)&"""")=$A$2)))) / S$7, ""-""))"),"-") -> - | T9: =IFERROR(__xludf.DUMMYFUNCTION("IF(T$6="""", """", IFERROR(ROWS(FILTER('기록'!$F:$F, ('기록'!$D:$D=T$6) * ('기록'!$F:$F=2) * (IF($A$2=""전체"", TRUE, (YEAR('기록'!$A:$A)&"""")=$A$2)))) / T$7, ""-""))"),"-") -> - | U9: =IFERROR(__xludf.DUMMYFUNCTION("IF(U$6="""", """", IFERROR(ROWS(FILTER('기록'!$F:$F, ('기록'!$D:$D=U$6) * ('기록'!$F:$F=2) * (IF($A$2=""전체"", TRUE, (YEAR('기록'!$A:$A)&"""")=$A$2)))) / U$7, ""-""))"),"-") -> - | V9: =IFERROR(__xludf.DUMMYFUNCTION("IF(V$6="""", """", IFERROR(ROWS(FILTER('기록'!$F:$F, ('기록'!$D:$D=V$6) * ('기록'!$F:$F=2) * (IF($A$2=""전체"", TRUE, (YEAR('기록'!$A:$A)&"""")=$A$2)))) / V$7, ""-""))"),0.25) -> 0.25 | W9: =IFERROR(__xludf.DUMMYFUNCTION("IF(W$6="""", """", IFERROR(ROWS(FILTER('기록'!$F:$F, ('기록'!$D:$D=W$6) * ('기록'!$F:$F=2) * (IF($A$2=""전체"", TRUE, (YEAR('기록'!$A:$A)&"""")=$A$2)))) / W$7, ""-""))"),"-") -> - | X9: =IFERROR(__xludf.DUMMYFUNCTION("IF(X$6="""", """", IFERROR(ROWS(FILTER('기록'!$F:$F, ('기록'!$D:$D=X$6) * ('기록'!$F:$F=2) * (IF($A$2=""전체"", TRUE, (YEAR('기록'!$A:$A)&"""")=$A$2)))) / X$7, ""-""))"),"-") -> - | Y9: =IFERROR(__xludf.DUMMYFUNCTION("IF(Y$6="""", """", IFERROR(ROWS(FILTER('기록'!$F:$F, ('기록'!$D:$D=Y$6) * ('기록'!$F:$F=2) * (IF($A$2=""전체"", TRUE, (YEAR('기록'!$A:$A)&"""")=$A$2)))) / Y$7, ""-""))"),"-") -> - | Z9: =IFERROR(__xludf.DUMMYFUNCTION("IF(Z$6="""", """", IFERROR(ROWS(FILTER('기록'!$F:$F, ('기록'!$D:$D=Z$6) * ('기록'!$F:$F=2) * (IF($A$2=""전체"", TRUE, (YEAR('기록'!$A:$A)&"""")=$A$2)))) / Z$7, ""-""))"),"-") -> - | AA9: =IFERROR(__xludf.DUMMYFUNCTION("IF(AA$6="""", """", IFERROR(ROWS(FILTER('기록'!$F:$F, ('기록'!$D:$D=AA$6) * ('기록'!$F:$F=2) * (IF($A$2=""전체"", TRUE, (YEAR('기록'!$A:$A)&"""")=$A$2)))) / AA$7, ""-""))"),"-") -> - | AB9: =IFERROR(__xludf.DUMMYFUNCTION("IF(AB$6="""", """", IFERROR(ROWS(FILTER('기록'!$F:$F, ('기록'!$D:$D=AB$6) * ('기록'!$F:$F=2) * (IF($A$2=""전체"", TRUE, (YEAR('기록'!$A:$A)&"""")=$A$2)))) / AB$7, ""-""))"),"-") -> - | AC9: =IFERROR(__xludf.DUMMYFUNCTION("IF(AC$6="""", """", IFERROR(ROWS(FILTER('기록'!$F:$F, ('기록'!$D:$D=AC$6) * ('기록'!$F:$F=2) * (IF($A$2=""전체"", TRUE, (YEAR('기록'!$A:$A)&"""")=$A$2)))) / AC$7, ""-""))"),0.2222222222222222) -> 0.22222222 | AD9: =IFERROR(__xludf.DUMMYFUNCTION("IF(AD$6="""", """", IFERROR(ROWS(FILTER('기록'!$F:$F, ('기록'!$D:$D=AD$6) * ('기록'!$F:$F=2) * (IF($A$2=""전체"", TRUE, (YEAR('기록'!$A:$A)&"""")=$A$2)))) / AD$7, ""-""))"),"-") -> - | AE9: =IFERROR(__xludf.DUMMYFUNCTION("IF(AE$6="""", """", IFERROR(ROWS(FILTER('기록'!$F:$F, ('기록'!$D:$D=AE$6) * ('기록'!$F:$F=2) * (IF($A$2=""전체"", TRUE, (YEAR('기록'!$A:$A)&"""")=$A$2)))) / AE$7, ""-""))"),"-") -> - | AF9: =IFERROR(__xludf.DUMMYFUNCTION("IF(AF$6="""", """", IFERROR(ROWS(FILTER('기록'!$F:$F, ('기록'!$D:$D=AF$6) * ('기록'!$F:$F=2) * (IF($A$2=""전체"", TRUE, (YEAR('기록'!$A:$A)&"""")=$A$2)))) / AF$7, ""-""))"),"-") -> - | AG9: =IFERROR(__xludf.DUMMYFUNCTION("IF(AG$6="""", """", IFERROR(ROWS(FILTER('기록'!$F:$F, ('기록'!$D:$D=AG$6) * ('기록'!$F:$F=2) * (IF($A$2=""전체"", TRUE, (YEAR('기록'!$A:$A)&"""")=$A$2)))) / AG$7, ""-""))"),0.25) -> 0.25 | AH9: =IFERROR(__xludf.DUMMYFUNCTION("IF(AH$6="""", """", IFERROR(ROWS(FILTER('기록'!$F:$F, ('기록'!$D:$D=AH$6) * ('기록'!$F:$F=2) * (IF($A$2=""전체"", TRUE, (YEAR('기록'!$A:$A)&"""")=$A$2)))) / AH$7, ""-""))"),0.3333333333333333) -> 0.33333333 | AI9: =IFERROR(__xludf.DUMMYFUNCTION("IF(AI$6="""", """", IFERROR(ROWS(FILTER('기록'!$F:$F, ('기록'!$D:$D=AI$6) * ('기록'!$F:$F=2) * (IF($A$2=""전체"", TRUE, (YEAR('기록'!$A:$A)&"""")=$A$2)))) / AI$7, ""-""))"),"-") -> -
B10: 3위율 | C10: =IFERROR(__xludf.DUMMYFUNCTION("IF(C$6="""", """", IFERROR(ROWS(FILTER('기록'!$F:$F, ('기록'!$D:$D=C$6) * ('기록'!$F:$F=3) * (IF($A$2=""전체"", TRUE, (YEAR('기록'!$A:$A)&"""")=$A$2)))) / C$7, ""-""))"),0.15) -> 0.15 | D10: =IFERROR(__xludf.DUMMYFUNCTION("IF(D$6="""", """", IFERROR(ROWS(FILTER('기록'!$F:$F, ('기록'!$D:$D=D$6) * ('기록'!$F:$F=3) * (IF($A$2=""전체"", TRUE, (YEAR('기록'!$A:$A)&"""")=$A$2)))) / D$7, ""-""))"),0.3333333333333333) -> 0.33333333 | E10: =IFERROR(__xludf.DUMMYFUNCTION("IF(E$6="""", """", IFERROR(ROWS(FILTER('기록'!$F:$F, ('기록'!$D:$D=E$6) * ('기록'!$F:$F=3) * (IF($A$2=""전체"", TRUE, (YEAR('기록'!$A:$A)&"""")=$A$2)))) / E$7, ""-""))"),0.10526315789473684) -> 0.10526316 | F10: =IFERROR(__xludf.DUMMYFUNCTION("IF(F$6="""", """", IFERROR(ROWS(FILTER('기록'!$F:$F, ('기록'!$D:$D=F$6) * ('기록'!$F:$F=3) * (IF($A$2=""전체"", TRUE, (YEAR('기록'!$A:$A)&"""")=$A$2)))) / F$7, ""-""))"),0.21428571428571427) -> 0.21428571 | G10: =IFERROR(__xludf.DUMMYFUNCTION("IF(G$6="""", """", IFERROR(ROWS(FILTER('기록'!$F:$F, ('기록'!$D:$D=G$6) * ('기록'!$F:$F=3) * (IF($A$2=""전체"", TRUE, (YEAR('기록'!$A:$A)&"""")=$A$2)))) / G$7, ""-""))"),0.21052631578947367) -> 0.21052632 | H10: =IFERROR(__xludf.DUMMYFUNCTION("IF(H$6="""", """", IFERROR(ROWS(FILTER('기록'!$F:$F, ('기록'!$D:$D=H$6) * ('기록'!$F:$F=3) * (IF($A$2=""전체"", TRUE, (YEAR('기록'!$A:$A)&"""")=$A$2)))) / H$7, ""-""))"),0.3) -> 0.3 | I10: =IFERROR(__xludf.DUMMYFUNCTION("IF(I$6="""", """", IFERROR(ROWS(FILTER('기록'!$F:$F, ('기록'!$D:$D=I$6) * ('기록'!$F:$F=3) * (IF($A$2=""전체"", TRUE, (YEAR('기록'!$A:$A)&"""")=$A$2)))) / I$7, ""-""))"),0.42857142857142855) -> 0.42857143 | J10: =IFERROR(__xludf.DUMMYFUNCTION("IF(J$6="""", """", IFERROR(ROWS(FILTER('기록'!$F:$F, ('기록'!$D:$D=J$6) * ('기록'!$F:$F=3) * (IF($A$2=""전체"", TRUE, (YEAR('기록'!$A:$A)&"""")=$A$2)))) / J$7, ""-""))"),"-") -> - | K10: =IFERROR(__xludf.DUMMYFUNCTION("IF(K$6="""", """", IFERROR(ROWS(FILTER('기록'!$F:$F, ('기록'!$D:$D=K$6) * ('기록'!$F:$F=3) * (IF($A$2=""전체"", TRUE, (YEAR('기록'!$A:$A)&"""")=$A$2)))) / K$7, ""-""))"),"-") -> - | L10: =IFERROR(__xludf.DUMMYFUNCTION("IF(L$6="""", """", IFERROR(ROWS(FILTER('기록'!$F:$F, ('기록'!$D:$D=L$6) * ('기록'!$F:$F=3) * (IF($A$2=""전체"", TRUE, (YEAR('기록'!$A:$A)&"""")=$A$2)))) / L$7, ""-""))"),0.17647058823529413) -> 0.17647059 | M10: =IFERROR(__xludf.DUMMYFUNCTION("IF(M$6="""", """", IFERROR(ROWS(FILTER('기록'!$F:$F, ('기록'!$D:$D=M$6) * ('기록'!$F:$F=3) * (IF($A$2=""전체"", TRUE, (YEAR('기록'!$A:$A)&"""")=$A$2)))) / M$7, ""-""))"),0.2972972972972973) -> 0.2972973 | N10: =IFERROR(__xludf.DUMMYFUNCTION("IF(N$6="""", """", IFERROR(ROWS(FILTER('기록'!$F:$F, ('기록'!$D:$D=N$6) * ('기록'!$F:$F=3) * (IF($A$2=""전체"", TRUE, (YEAR('기록'!$A:$A)&"""")=$A$2)))) / N$7, ""-""))"),"-") -> - | O10: =IFERROR(__xludf.DUMMYFUNCTION("IF(O$6="""", """", IFERROR(ROWS(FILTER('기록'!$F:$F, ('기록'!$D:$D=O$6) * ('기록'!$F:$F=3) * (IF($A$2=""전체"", TRUE, (YEAR('기록'!$A:$A)&"""")=$A$2)))) / O$7, ""-""))"),0.2) -> 0.2 | P10: =IFERROR(__xludf.DUMMYFUNCTION("IF(P$6="""", """", IFERROR(ROWS(FILTER('기록'!$F:$F, ('기록'!$D:$D=P$6) * ('기록'!$F:$F=3) * (IF($A$2=""전체"", TRUE, (YEAR('기록'!$A:$A)&"""")=$A$2)))) / P$7, ""-""))"),"-") -> - | Q10: =IFERROR(__xludf.DUMMYFUNCTION("IF(Q$6="""", """", IFERROR(ROWS(FILTER('기록'!$F:$F, ('기록'!$D:$D=Q$6) * ('기록'!$F:$F=3) * (IF($A$2=""전체"", TRUE, (YEAR('기록'!$A:$A)&"""")=$A$2)))) / Q$7, ""-""))"),"-") -> - | R10: =IFERROR(__xludf.DUMMYFUNCTION("IF(R$6="""", """", IFERROR(ROWS(FILTER('기록'!$F:$F, ('기록'!$D:$D=R$6) * ('기록'!$F:$F=3) * (IF($A$2=""전체"", TRUE, (YEAR('기록'!$A:$A)&"""")=$A$2)))) / R$7, ""-""))"),"-") -> - | S10: =IFERROR(__xludf.DUMMYFUNCTION("IF(S$6="""", """", IFERROR(ROWS(FILTER('기록'!$F:$F, ('기록'!$D:$D=S$6) * ('기록'!$F:$F=3) * (IF($A$2=""전체"", TRUE, (YEAR('기록'!$A:$A)&"""")=$A$2)))) / S$7, ""-""))"),"-") -> - | T10: =IFERROR(__xludf.DUMMYFUNCTION("IF(T$6="""", """", IFERROR(ROWS(FILTER('기록'!$F:$F, ('기록'!$D:$D=T$6) * ('기록'!$F:$F=3) * (IF($A$2=""전체"", TRUE, (YEAR('기록'!$A:$A)&"""")=$A$2)))) / T$7, ""-""))"),"-") -> - | U10: =IFERROR(__xludf.DUMMYFUNCTION("IF(U$6="""", """", IFERROR(ROWS(FILTER('기록'!$F:$F, ('기록'!$D:$D=U$6) * ('기록'!$F:$F=3) * (IF($A$2=""전체"", TRUE, (YEAR('기록'!$A:$A)&"""")=$A$2)))) / U$7, ""-""))"),"-") -> - | V10: =IFERROR(__xludf.DUMMYFUNCTION("IF(V$6="""", """", IFERROR(ROWS(FILTER('기록'!$F:$F, ('기록'!$D:$D=V$6) * ('기록'!$F:$F=3) * (IF($A$2=""전체"", TRUE, (YEAR('기록'!$A:$A)&"""")=$A$2)))) / V$7, ""-""))"),0.4166666666666667) -> 0.41666667 | W10: =IFERROR(__xludf.DUMMYFUNCTION("IF(W$6="""", """", IFERROR(ROWS(FILTER('기록'!$F:$F, ('기록'!$D:$D=W$6) * ('기록'!$F:$F=3) * (IF($A$2=""전체"", TRUE, (YEAR('기록'!$A:$A)&"""")=$A$2)))) / W$7, ""-""))"),"-") -> - | X10: =IFERROR(__xludf.DUMMYFUNCTION("IF(X$6="""", """", IFERROR(ROWS(FILTER('기록'!$F:$F, ('기록'!$D:$D=X$6) * ('기록'!$F:$F=3) * (IF($A$2=""전체"", TRUE, (YEAR('기록'!$A:$A)&"""")=$A$2)))) / X$7, ""-""))"),"-") -> - | Y10: =IFERROR(__xludf.DUMMYFUNCTION("IF(Y$6="""", """", IFERROR(ROWS(FILTER('기록'!$F:$F, ('기록'!$D:$D=Y$6) * ('기록'!$F:$F=3) * (IF($A$2=""전체"", TRUE, (YEAR('기록'!$A:$A)&"""")=$A$2)))) / Y$7, ""-""))"),"-") -> - | Z10: =IFERROR(__xludf.DUMMYFUNCTION("IF(Z$6="""", """", IFERROR(ROWS(FILTER('기록'!$F:$F, ('기록'!$D:$D=Z$6) * ('기록'!$F:$F=3) * (IF($A$2=""전체"", TRUE, (YEAR('기록'!$A:$A)&"""")=$A$2)))) / Z$7, ""-""))"),"-") -> - | AA10: =IFERROR(__xludf.DUMMYFUNCTION("IF(AA$6="""", """", IFERROR(ROWS(FILTER('기록'!$F:$F, ('기록'!$D:$D=AA$6) * ('기록'!$F:$F=3) * (IF($A$2=""전체"", TRUE, (YEAR('기록'!$A:$A)&"""")=$A$2)))) / AA$7, ""-""))"),"-") -> - | AB10: =IFERROR(__xludf.DUMMYFUNCTION("IF(AB$6="""", """", IFERROR(ROWS(FILTER('기록'!$F:$F, ('기록'!$D:$D=AB$6) * ('기록'!$F:$F=3) * (IF($A$2=""전체"", TRUE, (YEAR('기록'!$A:$A)&"""")=$A$2)))) / AB$7, ""-""))"),"-") -> - | AC10: =IFERROR(__xludf.DUMMYFUNCTION("IF(AC$6="""", """", IFERROR(ROWS(FILTER('기록'!$F:$F, ('기록'!$D:$D=AC$6) * ('기록'!$F:$F=3) * (IF($A$2=""전체"", TRUE, (YEAR('기록'!$A:$A)&"""")=$A$2)))) / AC$7, ""-""))"),0.3333333333333333) -> 0.33333333 | AD10: =IFERROR(__xludf.DUMMYFUNCTION("IF(AD$6="""", """", IFERROR(ROWS(FILTER('기록'!$F:$F, ('기록'!$D:$D=AD$6) * ('기록'!$F:$F=3) * (IF($A$2=""전체"", TRUE, (YEAR('기록'!$A:$A)&"""")=$A$2)))) / AD$7, ""-""))"),"-") -> - | AE10: =IFERROR(__xludf.DUMMYFUNCTION("IF(AE$6="""", """", IFERROR(ROWS(FILTER('기록'!$F:$F, ('기록'!$D:$D=AE$6) * ('기록'!$F:$F=3) * (IF($A$2=""전체"", TRUE, (YEAR('기록'!$A:$A)&"""")=$A$2)))) / AE$7, ""-""))"),"-") -> - | AF10: =IFERROR(__xludf.DUMMYFUNCTION("IF(AF$6="""", """", IFERROR(ROWS(FILTER('기록'!$F:$F, ('기록'!$D:$D=AF$6) * ('기록'!$F:$F=3) * (IF($A$2=""전체"", TRUE, (YEAR('기록'!$A:$A)&"""")=$A$2)))) / AF$7, ""-""))"),"-") -> - | AG10: =IFERROR(__xludf.DUMMYFUNCTION("IF(AG$6="""", """", IFERROR(ROWS(FILTER('기록'!$F:$F, ('기록'!$D:$D=AG$6) * ('기록'!$F:$F=3) * (IF($A$2=""전체"", TRUE, (YEAR('기록'!$A:$A)&"""")=$A$2)))) / AG$7, ""-""))"),"-") -> - | AH10: =IFERROR(__xludf.DUMMYFUNCTION("IF(AH$6="""", """", IFERROR(ROWS(FILTER('기록'!$F:$F, ('기록'!$D:$D=AH$6) * ('기록'!$F:$F=3) * (IF($A$2=""전체"", TRUE, (YEAR('기록'!$A:$A)&"""")=$A$2)))) / AH$7, ""-""))"),0.3333333333333333) -> 0.33333333 | AI10: =IFERROR(__xludf.DUMMYFUNCTION("IF(AI$6="""", """", IFERROR(ROWS(FILTER('기록'!$F:$F, ('기록'!$D:$D=AI$6) * ('기록'!$F:$F=3) * (IF($A$2=""전체"", TRUE, (YEAR('기록'!$A:$A)&"""")=$A$2)))) / AI$7, ""-""))"),0.3333333333333333) -> 0.33333333
B11: 4위율 | C11: =IFERROR(__xludf.DUMMYFUNCTION("IF(C$6="""", """", IFERROR(ROWS(FILTER('기록'!$F:$F, ('기록'!$D:$D=C$6) * ('기록'!$F:$F=4) * (IF($A$2=""전체"", TRUE, (YEAR('기록'!$A:$A)&"""")=$A$2)))) / C$7, ""-""))"),0.3) -> 0.3 | D11: =IFERROR(__xludf.DUMMYFUNCTION("IF(D$6="""", """", IFERROR(ROWS(FILTER('기록'!$F:$F, ('기록'!$D:$D=D$6) * ('기록'!$F:$F=4) * (IF($A$2=""전체"", TRUE, (YEAR('기록'!$A:$A)&"""")=$A$2)))) / D$7, ""-""))"),0.08333333333333333) -> 0.083333333 | E11: =IFERROR(__xludf.DUMMYFUNCTION("IF(E$6="""", """", IFERROR(ROWS(FILTER('기록'!$F:$F, ('기록'!$D:$D=E$6) * ('기록'!$F:$F=4) * (IF($A$2=""전체"", TRUE, (YEAR('기록'!$A:$A)&"""")=$A$2)))) / E$7, ""-""))"),0.42105263157894735) -> 0.42105263 | F11: =IFERROR(__xludf.DUMMYFUNCTION("IF(F$6="""", """", IFERROR(ROWS(FILTER('기록'!$F:$F, ('기록'!$D:$D=F$6) * ('기록'!$F:$F=4) * (IF($A$2=""전체"", TRUE, (YEAR('기록'!$A:$A)&"""")=$A$2)))) / F$7, ""-""))"),0.35714285714285715) -> 0.35714286 | G11: =IFERROR(__xludf.DUMMYFUNCTION("IF(G$6="""", """", IFERROR(ROWS(FILTER('기록'!$F:$F, ('기록'!$D:$D=G$6) * ('기록'!$F:$F=4) * (IF($A$2=""전체"", TRUE, (YEAR('기록'!$A:$A)&"""")=$A$2)))) / G$7, ""-""))"),0.2631578947368421) -> 0.26315789 | H11: =IFERROR(__xludf.DUMMYFUNCTION("IF(H$6="""", """", IFERROR(ROWS(FILTER('기록'!$F:$F, ('기록'!$D:$D=H$6) * ('기록'!$F:$F=4) * (IF($A$2=""전체"", TRUE, (YEAR('기록'!$A:$A)&"""")=$A$2)))) / H$7, ""-""))"),0.3) -> 0.3 | I11: =IFERROR(__xludf.DUMMYFUNCTION("IF(I$6="""", """", IFERROR(ROWS(FILTER('기록'!$F:$F, ('기록'!$D:$D=I$6) * ('기록'!$F:$F=4) * (IF($A$2=""전체"", TRUE, (YEAR('기록'!$A:$A)&"""")=$A$2)))) / I$7, ""-""))"),0.14285714285714285) -> 0.14285714 | J11: =IFERROR(__xludf.DUMMYFUNCTION("IF(J$6="""", """", IFERROR(ROWS(FILTER('기록'!$F:$F, ('기록'!$D:$D=J$6) * ('기록'!$F:$F=4) * (IF($A$2=""전체"", TRUE, (YEAR('기록'!$A:$A)&"""")=$A$2)))) / J$7, ""-""))"),"-") -> - | K11: =IFERROR(__xludf.DUMMYFUNCTION("IF(K$6="""", """", IFERROR(ROWS(FILTER('기록'!$F:$F, ('기록'!$D:$D=K$6) * ('기록'!$F:$F=4) * (IF($A$2=""전체"", TRUE, (YEAR('기록'!$A:$A)&"""")=$A$2)))) / K$7, ""-""))"),0.42857142857142855) -> 0.42857143 | L11: =IFERROR(__xludf.DUMMYFUNCTION("IF(L$6="""", """", IFERROR(ROWS(FILTER('기록'!$F:$F, ('기록'!$D:$D=L$6) * ('기록'!$F:$F=4) * (IF($A$2=""전체"", TRUE, (YEAR('기록'!$A:$A)&"""")=$A$2)))) / L$7, ""-""))"),0.23529411764705882) -> 0.23529412 | M11: =IFERROR(__xludf.DUMMYFUNCTION("IF(M$6="""", """", IFERROR(ROWS(FILTER('기록'!$F:$F, ('기록'!$D:$D=M$6) * ('기록'!$F:$F=4) * (IF($A$2=""전체"", TRUE, (YEAR('기록'!$A:$A)&"""")=$A$2)))) / M$7, ""-""))"),0.10810810810810811) -> 0.10810811 | N11: =IFERROR(__xludf.DUMMYFUNCTION("IF(N$6="""", """", IFERROR(ROWS(FILTER('기록'!$F:$F, ('기록'!$D:$D=N$6) * ('기록'!$F:$F=4) * (IF($A$2=""전체"", TRUE, (YEAR('기록'!$A:$A)&"""")=$A$2)))) / N$7, ""-""))"),"-") -> - | O11: =IFERROR(__xludf.DUMMYFUNCTION("IF(O$6="""", """", IFERROR(ROWS(FILTER('기록'!$F:$F, ('기록'!$D:$D=O$6) * ('기록'!$F:$F=4) * (IF($A$2=""전체"", TRUE, (YEAR('기록'!$A:$A)&"""")=$A$2)))) / O$7, ""-""))"),0.6) -> 0.6 | P11: =IFERROR(__xludf.DUMMYFUNCTION("IF(P$6="""", """", IFERROR(ROWS(FILTER('기록'!$F:$F, ('기록'!$D:$D=P$6) * ('기록'!$F:$F=4) * (IF($A$2=""전체"", TRUE, (YEAR('기록'!$A:$A)&"""")=$A$2)))) / P$7, ""-""))"),"-") -> - | Q11: =IFERROR(__xludf.DUMMYFUNCTION("IF(Q$6="""", """", IFERROR(ROWS(FILTER('기록'!$F:$F, ('기록'!$D:$D=Q$6) * ('기록'!$F:$F=4) * (IF($A$2=""전체"", TRUE, (YEAR('기록'!$A:$A)&"""")=$A$2)))) / Q$7, ""-""))"),"-") -> - | R11: =IFERROR(__xludf.DUMMYFUNCTION("IF(R$6="""", """", IFERROR(ROWS(FILTER('기록'!$F:$F, ('기록'!$D:$D=R$6) * ('기록'!$F:$F=4) * (IF($A$2=""전체"", TRUE, (YEAR('기록'!$A:$A)&"""")=$A$2)))) / R$7, ""-""))"),"-") -> - | S11: =IFERROR(__xludf.DUMMYFUNCTION("IF(S$6="""", """", IFERROR(ROWS(FILTER('기록'!$F:$F, ('기록'!$D:$D=S$6) * ('기록'!$F:$F=4) * (IF($A$2=""전체"", TRUE, (YEAR('기록'!$A:$A)&"""")=$A$2)))) / S$7, ""-""))"),"-") -> - | T11: =IFERROR(__xludf.DUMMYFUNCTION("IF(T$6="""", """", IFERROR(ROWS(FILTER('기록'!$F:$F, ('기록'!$D:$D=T$6) * ('기록'!$F:$F=4) * (IF($A$2=""전체"", TRUE, (YEAR('기록'!$A:$A)&"""")=$A$2)))) / T$7, ""-""))"),"-") -> - | U11: =IFERROR(__xludf.DUMMYFUNCTION("IF(U$6="""", """", IFERROR(ROWS(FILTER('기록'!$F:$F, ('기록'!$D:$D=U$6) * ('기록'!$F:$F=4) * (IF($A$2=""전체"", TRUE, (YEAR('기록'!$A:$A)&"""")=$A$2)))) / U$7, ""-""))"),"-") -> - | V11: =IFERROR(__xludf.DUMMYFUNCTION("IF(V$6="""", """", IFERROR(ROWS(FILTER('기록'!$F:$F, ('기록'!$D:$D=V$6) * ('기록'!$F:$F=4) * (IF($A$2=""전체"", TRUE, (YEAR('기록'!$A:$A)&"""")=$A$2)))) / V$7, ""-""))"),0.16666666666666666) -> 0.16666667 | W11: =IFERROR(__xludf.DUMMYFUNCTION("IF(W$6="""", """", IFERROR(ROWS(FILTER('기록'!$F:$F, ('기록'!$D:$D=W$6) * ('기록'!$F:$F=4) * (IF($A$2=""전체"", TRUE, (YEAR('기록'!$A:$A)&"""")=$A$2)))) / W$7, ""-""))"),"-") -> - | X11: =IFERROR(__xludf.DUMMYFUNCTION("IF(X$6="""", """", IFERROR(ROWS(FILTER('기록'!$F:$F, ('기록'!$D:$D=X$6) * ('기록'!$F:$F=4) * (IF($A$2=""전체"", TRUE, (YEAR('기록'!$A:$A)&"""")=$A$2)))) / X$7, ""-""))"),"-") -> - | Y11: =IFERROR(__xludf.DUMMYFUNCTION("IF(Y$6="""", """", IFERROR(ROWS(FILTER('기록'!$F:$F, ('기록'!$D:$D=Y$6) * ('기록'!$F:$F=4) * (IF($A$2=""전체"", TRUE, (YEAR('기록'!$A:$A)&"""")=$A$2)))) / Y$7, ""-""))"),"-") -> - | Z11: =IFERROR(__xludf.DUMMYFUNCTION("IF(Z$6="""", """", IFERROR(ROWS(FILTER('기록'!$F:$F, ('기록'!$D:$D=Z$6) * ('기록'!$F:$F=4) * (IF($A$2=""전체"", TRUE, (YEAR('기록'!$A:$A)&"""")=$A$2)))) / Z$7, ""-""))"),"-") -> - | AA11: =IFERROR(__xludf.DUMMYFUNCTION("IF(AA$6="""", """", IFERROR(ROWS(FILTER('기록'!$F:$F, ('기록'!$D:$D=AA$6) * ('기록'!$F:$F=4) * (IF($A$2=""전체"", TRUE, (YEAR('기록'!$A:$A)&"""")=$A$2)))) / AA$7, ""-""))"),"-") -> - | AB11: =IFERROR(__xludf.DUMMYFUNCTION("IF(AB$6="""", """", IFERROR(ROWS(FILTER('기록'!$F:$F, ('기록'!$D:$D=AB$6) * ('기록'!$F:$F=4) * (IF($A$2=""전체"", TRUE, (YEAR('기록'!$A:$A)&"""")=$A$2)))) / AB$7, ""-""))"),"-") -> - | AC11: =IFERROR(__xludf.DUMMYFUNCTION("IF(AC$6="""", """", IFERROR(ROWS(FILTER('기록'!$F:$F, ('기록'!$D:$D=AC$6) * ('기록'!$F:$F=4) * (IF($A$2=""전체"", TRUE, (YEAR('기록'!$A:$A)&"""")=$A$2)))) / AC$7, ""-""))"),0.4444444444444444) -> 0.44444444 | AD11: =IFERROR(__xludf.DUMMYFUNCTION("IF(AD$6="""", """", IFERROR(ROWS(FILTER('기록'!$F:$F, ('기록'!$D:$D=AD$6) * ('기록'!$F:$F=4) * (IF($A$2=""전체"", TRUE, (YEAR('기록'!$A:$A)&"""")=$A$2)))) / AD$7, ""-""))"),"-") -> - | AE11: =IFERROR(__xludf.DUMMYFUNCTION("IF(AE$6="""", """", IFERROR(ROWS(FILTER('기록'!$F:$F, ('기록'!$D:$D=AE$6) * ('기록'!$F:$F=4) * (IF($A$2=""전체"", TRUE, (YEAR('기록'!$A:$A)&"""")=$A$2)))) / AE$7, ""-""))"),"-") -> - | AF11: =IFERROR(__xludf.DUMMYFUNCTION("IF(AF$6="""", """", IFERROR(ROWS(FILTER('기록'!$F:$F, ('기록'!$D:$D=AF$6) * ('기록'!$F:$F=4) * (IF($A$2=""전체"", TRUE, (YEAR('기록'!$A:$A)&"""")=$A$2)))) / AF$7, ""-""))"),"-") -> - | AG11: =IFERROR(__xludf.DUMMYFUNCTION("IF(AG$6="""", """", IFERROR(ROWS(FILTER('기록'!$F:$F, ('기록'!$D:$D=AG$6) * ('기록'!$F:$F=4) * (IF($A$2=""전체"", TRUE, (YEAR('기록'!$A:$A)&"""")=$A$2)))) / AG$7, ""-""))"),0.5) -> 0.5 | AH11: =IFERROR(__xludf.DUMMYFUNCTION("IF(AH$6="""", """", IFERROR(ROWS(FILTER('기록'!$F:$F, ('기록'!$D:$D=AH$6) * ('기록'!$F:$F=4) * (IF($A$2=""전체"", TRUE, (YEAR('기록'!$A:$A)&"""")=$A$2)))) / AH$7, ""-""))"),0.25) -> 0.25 | AI11: =IFERROR(__xludf.DUMMYFUNCTION("IF(AI$6="""", """", IFERROR(ROWS(FILTER('기록'!$F:$F, ('기록'!$D:$D=AI$6) * ('기록'!$F:$F=4) * (IF($A$2=""전체"", TRUE, (YEAR('기록'!$A:$A)&"""")=$A$2)))) / AI$7, ""-""))"),0.3333333333333333) -> 0.33333333
B12: 토비율 | C12: =IFERROR(__xludf.DUMMYFUNCTION("IF(C$6="""", """", IFERROR(ROWS(FILTER('기록'!$E:$E, ('기록'!$D:$D=C$6) * ('기록'!$E:$E < 0) * (IF($A$2=""전체"", TRUE, (YEAR('기록'!$A:$A)&"""")=$A$2)))) / C$7, ""-""))"),0.05) -> 0.05 | D12: =IFERROR(__xludf.DUMMYFUNCTION("IF(D$6="""", """", IFERROR(ROWS(FILTER('기록'!$E:$E, ('기록'!$D:$D=D$6) * ('기록'!$E:$E < 0) * (IF($A$2=""전체"", TRUE, (YEAR('기록'!$A:$A)&"""")=$A$2)))) / D$7, ""-""))"),0.020833333333333332) -> 0.020833333 | E12: =IFERROR(__xludf.DUMMYFUNCTION("IF(E$6="""", """", IFERROR(ROWS(FILTER('기록'!$E:$E, ('기록'!$D:$D=E$6) * ('기록'!$E:$E < 0) * (IF($A$2=""전체"", TRUE, (YEAR('기록'!$A:$A)&"""")=$A$2)))) / E$7, ""-""))"),0.05263157894736842) -> 0.052631579 | F12: =IFERROR(__xludf.DUMMYFUNCTION("IF(F$6="""", """", IFERROR(ROWS(FILTER('기록'!$E:$E, ('기록'!$D:$D=F$6) * ('기록'!$E:$E < 0) * (IF($A$2=""전체"", TRUE, (YEAR('기록'!$A:$A)&"""")=$A$2)))) / F$7, ""-""))"),0.10714285714285714) -> 0.10714286 | G12: =IFERROR(__xludf.DUMMYFUNCTION("IF(G$6="""", """", IFERROR(ROWS(FILTER('기록'!$E:$E, ('기록'!$D:$D=G$6) * ('기록'!$E:$E < 0) * (IF($A$2=""전체"", TRUE, (YEAR('기록'!$A:$A)&"""")=$A$2)))) / G$7, ""-""))"),0.10526315789473684) -> 0.10526316 | H12: =IFERROR(__xludf.DUMMYFUNCTION("IF(H$6="""", """", IFERROR(ROWS(FILTER('기록'!$E:$E, ('기록'!$D:$D=H$6) * ('기록'!$E:$E < 0) * (IF($A$2=""전체"", TRUE, (YEAR('기록'!$A:$A)&"""")=$A$2)))) / H$7, ""-""))"),0.1) -> 0.1 | I12: =IFERROR(__xludf.DUMMYFUNCTION("IF(I$6="""", """", IFERROR(ROWS(FILTER('기록'!$E:$E, ('기록'!$D:$D=I$6) * ('기록'!$E:$E < 0) * (IF($A$2=""전체"", TRUE, (YEAR('기록'!$A:$A)&"""")=$A$2)))) / I$7, ""-""))"),0.14285714285714285) -> 0.14285714 | J12: =IFERROR(__xludf.DUMMYFUNCTION("IF(J$6="""", """", IFERROR(ROWS(FILTER('기록'!$E:$E, ('기록'!$D:$D=J$6) * ('기록'!$E:$E < 0) * (IF($A$2=""전체"", TRUE, (YEAR('기록'!$A:$A)&"""")=$A$2)))) / J$7, ""-""))"),"-") -> - | K12: =IFERROR(__xludf.DUMMYFUNCTION("IF(K$6="""", """", IFERROR(ROWS(FILTER('기록'!$E:$E, ('기록'!$D:$D=K$6) * ('기록'!$E:$E < 0) * (IF($A$2=""전체"", TRUE, (YEAR('기록'!$A:$A)&"""")=$A$2)))) / K$7, ""-""))"),0.42857142857142855) -> 0.42857143 | L12: =IFERROR(__xludf.DUMMYFUNCTION("IF(L$6="""", """", IFERROR(ROWS(FILTER('기록'!$E:$E, ('기록'!$D:$D=L$6) * ('기록'!$E:$E < 0) * (IF($A$2=""전체"", TRUE, (YEAR('기록'!$A:$A)&"""")=$A$2)))) / L$7, ""-""))"),0.058823529411764705) -> 0.058823529 | M12: =IFERROR(__xludf.DUMMYFUNCTION("IF(M$6="""", """", IFERROR(ROWS(FILTER('기록'!$E:$E, ('기록'!$D:$D=M$6) * ('기록'!$E:$E < 0) * (IF($A$2=""전체"", TRUE, (YEAR('기록'!$A:$A)&"""")=$A$2)))) / M$7, ""-""))"),0.02702702702702703) -> 0.027027027 | N12: =IFERROR(__xludf.DUMMYFUNCTION("IF(N$6="""", """", IFERROR(ROWS(FILTER('기록'!$E:$E, ('기록'!$D:$D=N$6) * ('기록'!$E:$E < 0) * (IF($A$2=""전체"", TRUE, (YEAR('기록'!$A:$A)&"""")=$A$2)))) / N$7, ""-""))"),"-") -> - | O12: =IFERROR(__xludf.DUMMYFUNCTION("IF(O$6="""", """", IFERROR(ROWS(FILTER('기록'!$E:$E, ('기록'!$D:$D=O$6) * ('기록'!$E:$E < 0) * (IF($A$2=""전체"", TRUE, (YEAR('기록'!$A:$A)&"""")=$A$2)))) / O$7, ""-""))"),0.2) -> 0.2 | P12: =IFERROR(__xludf.DUMMYFUNCTION("IF(P$6="""", """", IFERROR(ROWS(FILTER('기록'!$E:$E, ('기록'!$D:$D=P$6) * ('기록'!$E:$E < 0) * (IF($A$2=""전체"", TRUE, (YEAR('기록'!$A:$A)&"""")=$A$2)))) / P$7, ""-""))"),"-") -> - | Q12: =IFERROR(__xludf.DUMMYFUNCTION("IF(Q$6="""", """", IFERROR(ROWS(FILTER('기록'!$E:$E, ('기록'!$D:$D=Q$6) * ('기록'!$E:$E < 0) * (IF($A$2=""전체"", TRUE, (YEAR('기록'!$A:$A)&"""")=$A$2)))) / Q$7, ""-""))"),"-") -> - | R12: =IFERROR(__xludf.DUMMYFUNCTION("IF(R$6="""", """", IFERROR(ROWS(FILTER('기록'!$E:$E, ('기록'!$D:$D=R$6) * ('기록'!$E:$E < 0) * (IF($A$2=""전체"", TRUE, (YEAR('기록'!$A:$A)&"""")=$A$2)))) / R$7, ""-""))"),"-") -> - | S12: =IFERROR(__xludf.DUMMYFUNCTION("IF(S$6="""", """", IFERROR(ROWS(FILTER('기록'!$E:$E, ('기록'!$D:$D=S$6) * ('기록'!$E:$E < 0) * (IF($A$2=""전체"", TRUE, (YEAR('기록'!$A:$A)&"""")=$A$2)))) / S$7, ""-""))"),"-") -> - | T12: =IFERROR(__xludf.DUMMYFUNCTION("IF(T$6="""", """", IFERROR(ROWS(FILTER('기록'!$E:$E, ('기록'!$D:$D=T$6) * ('기록'!$E:$E < 0) * (IF($A$2=""전체"", TRUE, (YEAR('기록'!$A:$A)&"""")=$A$2)))) / T$7, ""-""))"),"-") -> - | U12: =IFERROR(__xludf.DUMMYFUNCTION("IF(U$6="""", """", IFERROR(ROWS(FILTER('기록'!$E:$E, ('기록'!$D:$D=U$6) * ('기록'!$E:$E < 0) * (IF($A$2=""전체"", TRUE, (YEAR('기록'!$A:$A)&"""")=$A$2)))) / U$7, ""-""))"),"-") -> - | V12: =IFERROR(__xludf.DUMMYFUNCTION("IF(V$6="""", """", IFERROR(ROWS(FILTER('기록'!$E:$E, ('기록'!$D:$D=V$6) * ('기록'!$E:$E < 0) * (IF($A$2=""전체"", TRUE, (YEAR('기록'!$A:$A)&"""")=$A$2)))) / V$7, ""-""))"),"-") -> - | W12: =IFERROR(__xludf.DUMMYFUNCTION("IF(W$6="""", """", IFERROR(ROWS(FILTER('기록'!$E:$E, ('기록'!$D:$D=W$6) * ('기록'!$E:$E < 0) * (IF($A$2=""전체"", TRUE, (YEAR('기록'!$A:$A)&"""")=$A$2)))) / W$7, ""-""))"),"-") -> - | X12: =IFERROR(__xludf.DUMMYFUNCTION("IF(X$6="""", """", IFERROR(ROWS(FILTER('기록'!$E:$E, ('기록'!$D:$D=X$6) * ('기록'!$E:$E < 0) * (IF($A$2=""전체"", TRUE, (YEAR('기록'!$A:$A)&"""")=$A$2)))) / X$7, ""-""))"),"-") -> - | Y12: =IFERROR(__xludf.DUMMYFUNCTION("IF(Y$6="""", """", IFERROR(ROWS(FILTER('기록'!$E:$E, ('기록'!$D:$D=Y$6) * ('기록'!$E:$E < 0) * (IF($A$2=""전체"", TRUE, (YEAR('기록'!$A:$A)&"""")=$A$2)))) / Y$7, ""-""))"),"-") -> - | Z12: =IFERROR(__xludf.DUMMYFUNCTION("IF(Z$6="""", """", IFERROR(ROWS(FILTER('기록'!$E:$E, ('기록'!$D:$D=Z$6) * ('기록'!$E:$E < 0) * (IF($A$2=""전체"", TRUE, (YEAR('기록'!$A:$A)&"""")=$A$2)))) / Z$7, ""-""))"),"-") -> - | AA12: =IFERROR(__xludf.DUMMYFUNCTION("IF(AA$6="""", """", IFERROR(ROWS(FILTER('기록'!$E:$E, ('기록'!$D:$D=AA$6) * ('기록'!$E:$E < 0) * (IF($A$2=""전체"", TRUE, (YEAR('기록'!$A:$A)&"""")=$A$2)))) / AA$7, ""-""))"),"-") -> - | AB12: =IFERROR(__xludf.DUMMYFUNCTION("IF(AB$6="""", """", IFERROR(ROWS(FILTER('기록'!$E:$E, ('기록'!$D:$D=AB$6) * ('기록'!$E:$E < 0) * (IF($A$2=""전체"", TRUE, (YEAR('기록'!$A:$A)&"""")=$A$2)))) / AB$7, ""-""))"),"-") -> - | AC12: =IFERROR(__xludf.DUMMYFUNCTION("IF(AC$6="""", """", IFERROR(ROWS(FILTER('기록'!$E:$E, ('기록'!$D:$D=AC$6) * ('기록'!$E:$E < 0) * (IF($A$2=""전체"", TRUE, (YEAR('기록'!$A:$A)&"""")=$A$2)))) / AC$7, ""-""))"),0.1111111111111111) -> 0.11111111 | AD12: =IFERROR(__xludf.DUMMYFUNCTION("IF(AD$6="""", """", IFERROR(ROWS(FILTER('기록'!$E:$E, ('기록'!$D:$D=AD$6) * ('기록'!$E:$E < 0) * (IF($A$2=""전체"", TRUE, (YEAR('기록'!$A:$A)&"""")=$A$2)))) / AD$7, ""-""))"),"-") -> - | AE12: =IFERROR(__xludf.DUMMYFUNCTION("IF(AE$6="""", """", IFERROR(ROWS(FILTER('기록'!$E:$E, ('기록'!$D:$D=AE$6) * ('기록'!$E:$E < 0) * (IF($A$2=""전체"", TRUE, (YEAR('기록'!$A:$A)&"""")=$A$2)))) / AE$7, ""-""))"),"-") -> - | AF12: =IFERROR(__xludf.DUMMYFUNCTION("IF(AF$6="""", """", IFERROR(ROWS(FILTER('기록'!$E:$E, ('기록'!$D:$D=AF$6) * ('기록'!$E:$E < 0) * (IF($A$2=""전체"", TRUE, (YEAR('기록'!$A:$A)&"""")=$A$2)))) / AF$7, ""-""))"),"-") -> - | AG12: =IFERROR(__xludf.DUMMYFUNCTION("IF(AG$6="""", """", IFERROR(ROWS(FILTER('기록'!$E:$E, ('기록'!$D:$D=AG$6) * ('기록'!$E:$E < 0) * (IF($A$2=""전체"", TRUE, (YEAR('기록'!$A:$A)&"""")=$A$2)))) / AG$7, ""-""))"),0.25) -> 0.25 | AH12: =IFERROR(__xludf.DUMMYFUNCTION("IF(AH$6="""", """", IFERROR(ROWS(FILTER('기록'!$E:$E, ('기록'!$D:$D=AH$6) * ('기록'!$E:$E < 0) * (IF($A$2=""전체"", TRUE, (YEAR('기록'!$A:$A)&"""")=$A$2)))) / AH$7, ""-""))"),"-") -> - | AI12: =IFERROR(__xludf.DUMMYFUNCTION("IF(AI$6="""", """", IFERROR(ROWS(FILTER('기록'!$E:$E, ('기록'!$D:$D=AI$6) * ('기록'!$E:$E < 0) * (IF($A$2=""전체"", TRUE, (YEAR('기록'!$A:$A)&"""")=$A$2)))) / AI$7, ""-""))"),0.16666666666666666) -> 0.16666667
B13: 연대율 | C13: =IFERROR(__xludf.DUMMYFUNCTION("IF(C$6="""", """", IFERROR(ROWS(FILTER('기록'!$F:$F, ('기록'!$D:$D=C$6) * ('기록'!$F:$F<=2) * (IF($A$2=""전체"", TRUE, (YEAR('기록'!$A:$A)&"""")=$A$2)))) / C$7, ""-""))"),0.55) -> 0.55 | D13: =IFERROR(__xludf.DUMMYFUNCTION("IF(D$6="""", """", IFERROR(ROWS(FILTER('기록'!$F:$F, ('기록'!$D:$D=D$6) * ('기록'!$F:$F<=2) * (IF($A$2=""전체"", TRUE, (YEAR('기록'!$A:$A)&"""")=$A$2)))) / D$7, ""-""))"),0.5833333333333334) -> 0.58333333 | E13: =IFERROR(__xludf.DUMMYFUNCTION("IF(E$6="""", """", IFERROR(ROWS(FILTER('기록'!$F:$F, ('기록'!$D:$D=E$6) * ('기록'!$F:$F<=2) * (IF($A$2=""전체"", TRUE, (YEAR('기록'!$A:$A)&"""")=$A$2)))) / E$7, ""-""))"),0.47368421052631576) -> 0.47368421 | F13: =IFERROR(__xludf.DUMMYFUNCTION("IF(F$6="""", """", IFERROR(ROWS(FILTER('기록'!$F:$F, ('기록'!$D:$D=F$6) * ('기록'!$F:$F<=2) * (IF($A$2=""전체"", TRUE, (YEAR('기록'!$A:$A)&"""")=$A$2)))) / F$7, ""-""))"),0.42857142857142855) -> 0.42857143 | G13: =IFERROR(__xludf.DUMMYFUNCTION("IF(G$6="""", """", IFERROR(ROWS(FILTER('기록'!$F:$F, ('기록'!$D:$D=G$6) * ('기록'!$F:$F<=2) * (IF($A$2=""전체"", TRUE, (YEAR('기록'!$A:$A)&"""")=$A$2)))) / G$7, ""-""))"),0.5263157894736842) -> 0.52631579 | H13: =IFERROR(__xludf.DUMMYFUNCTION("IF(H$6="""", """", IFERROR(ROWS(FILTER('기록'!$F:$F, ('기록'!$D:$D=H$6) * ('기록'!$F:$F<=2) * (IF($A$2=""전체"", TRUE, (YEAR('기록'!$A:$A)&"""")=$A$2)))) / H$7, ""-""))"),0.4) -> 0.4 | I13: =IFERROR(__xludf.DUMMYFUNCTION("IF(I$6="""", """", IFERROR(ROWS(FILTER('기록'!$F:$F, ('기록'!$D:$D=I$6) * ('기록'!$F:$F<=2) * (IF($A$2=""전체"", TRUE, (YEAR('기록'!$A:$A)&"""")=$A$2)))) / I$7, ""-""))"),0.42857142857142855) -> 0.42857143 | J13: =IFERROR(__xludf.DUMMYFUNCTION("IF(J$6="""", """", IFERROR(ROWS(FILTER('기록'!$F:$F, ('기록'!$D:$D=J$6) * ('기록'!$F:$F<=2) * (IF($A$2=""전체"", TRUE, (YEAR('기록'!$A:$A)&"""")=$A$2)))) / J$7, ""-""))"),"-") -> - | K13: =IFERROR(__xludf.DUMMYFUNCTION("IF(K$6="""", """", IFERROR(ROWS(FILTER('기록'!$F:$F, ('기록'!$D:$D=K$6) * ('기록'!$F:$F<=2) * (IF($A$2=""전체"", TRUE, (YEAR('기록'!$A:$A)&"""")=$A$2)))) / K$7, ""-""))"),0.5714285714285714) -> 0.57142857 | L13: =IFERROR(__xludf.DUMMYFUNCTION("IF(L$6="""", """", IFERROR(ROWS(FILTER('기록'!$F:$F, ('기록'!$D:$D=L$6) * ('기록'!$F:$F<=2) * (IF($A$2=""전체"", TRUE, (YEAR('기록'!$A:$A)&"""")=$A$2)))) / L$7, ""-""))"),0.5882352941176471) -> 0.58823529 | M13: =IFERROR(__xludf.DUMMYFUNCTION("IF(M$6="""", """", IFERROR(ROWS(FILTER('기록'!$F:$F, ('기록'!$D:$D=M$6) * ('기록'!$F:$F<=2) * (IF($A$2=""전체"", TRUE, (YEAR('기록'!$A:$A)&"""")=$A$2)))) / M$7, ""-""))"),0.5945945945945946) -> 0.59459459 | N13: =IFERROR(__xludf.DUMMYFUNCTION("IF(N$6="""", """", IFERROR(ROWS(FILTER('기록'!$F:$F, ('기록'!$D:$D=N$6) * ('기록'!$F:$F<=2) * (IF($A$2=""전체"", TRUE, (YEAR('기록'!$A:$A)&"""")=$A$2)))) / N$7, ""-""))"),"-") -> - | O13: =IFERROR(__xludf.DUMMYFUNCTION("IF(O$6="""", """", IFERROR(ROWS(FILTER('기록'!$F:$F, ('기록'!$D:$D=O$6) * ('기록'!$F:$F<=2) * (IF($A$2=""전체"", TRUE, (YEAR('기록'!$A:$A)&"""")=$A$2)))) / O$7, ""-""))"),0.2) -> 0.2 | P13: =IFERROR(__xludf.DUMMYFUNCTION("IF(P$6="""", """", IFERROR(ROWS(FILTER('기록'!$F:$F, ('기록'!$D:$D=P$6) * ('기록'!$F:$F<=2) * (IF($A$2=""전체"", TRUE, (YEAR('기록'!$A:$A)&"""")=$A$2)))) / P$7, ""-""))"),"-") -> - | Q13: =IFERROR(__xludf.DUMMYFUNCTION("IF(Q$6="""", """", IFERROR(ROWS(FILTER('기록'!$F:$F, ('기록'!$D:$D=Q$6) * ('기록'!$F:$F<=2) * (IF($A$2=""전체"", TRUE, (YEAR('기록'!$A:$A)&"""")=$A$2)))) / Q$7, ""-""))"),"-") -> - | R13: =IFERROR(__xludf.DUMMYFUNCTION("IF(R$6="""", """", IFERROR(ROWS(FILTER('기록'!$F:$F, ('기록'!$D:$D=R$6) * ('기록'!$F:$F<=2) * (IF($A$2=""전체"", TRUE, (YEAR('기록'!$A:$A)&"""")=$A$2)))) / R$7, ""-""))"),"-") -> - | S13: =IFERROR(__xludf.DUMMYFUNCTION("IF(S$6="""", """", IFERROR(ROWS(FILTER('기록'!$F:$F, ('기록'!$D:$D=S$6) * ('기록'!$F:$F<=2) * (IF($A$2=""전체"", TRUE, (YEAR('기록'!$A:$A)&"""")=$A$2)))) / S$7, ""-""))"),"-") -> - | T13: =IFERROR(__xludf.DUMMYFUNCTION("IF(T$6="""", """", IFERROR(ROWS(FILTER('기록'!$F:$F, ('기록'!$D:$D=T$6) * ('기록'!$F:$F<=2) * (IF($A$2=""전체"", TRUE, (YEAR('기록'!$A:$A)&"""")=$A$2)))) / T$7, ""-""))"),"-") -> - | U13: =IFERROR(__xludf.DUMMYFUNCTION("IF(U$6="""", """", IFERROR(ROWS(FILTER('기록'!$F:$F, ('기록'!$D:$D=U$6) * ('기록'!$F:$F<=2) * (IF($A$2=""전체"", TRUE, (YEAR('기록'!$A:$A)&"""")=$A$2)))) / U$7, ""-""))"),"-") -> - | V13: =IFERROR(__xludf.DUMMYFUNCTION("IF(V$6="""", """", IFERROR(ROWS(FILTER('기록'!$F:$F, ('기록'!$D:$D=V$6) * ('기록'!$F:$F<=2) * (IF($A$2=""전체"", TRUE, (YEAR('기록'!$A:$A)&"""")=$A$2)))) / V$7, ""-""))"),0.4166666666666667) -> 0.41666667 | W13: =IFERROR(__xludf.DUMMYFUNCTION("IF(W$6="""", """", IFERROR(ROWS(FILTER('기록'!$F:$F, ('기록'!$D:$D=W$6) * ('기록'!$F:$F<=2) * (IF($A$2=""전체"", TRUE, (YEAR('기록'!$A:$A)&"""")=$A$2)))) / W$7, ""-""))"),"-") -> - | X13: =IFERROR(__xludf.DUMMYFUNCTION("IF(X$6="""", """", IFERROR(ROWS(FILTER('기록'!$F:$F, ('기록'!$D:$D=X$6) * ('기록'!$F:$F<=2) * (IF($A$2=""전체"", TRUE, (YEAR('기록'!$A:$A)&"""")=$A$2)))) / X$7, ""-""))"),"-") -> - | Y13: =IFERROR(__xludf.DUMMYFUNCTION("IF(Y$6="""", """", IFERROR(ROWS(FILTER('기록'!$F:$F, ('기록'!$D:$D=Y$6) * ('기록'!$F:$F<=2) * (IF($A$2=""전체"", TRUE, (YEAR('기록'!$A:$A)&"""")=$A$2)))) / Y$7, ""-""))"),"-") -> - | Z13: =IFERROR(__xludf.DUMMYFUNCTION("IF(Z$6="""", """", IFERROR(ROWS(FILTER('기록'!$F:$F, ('기록'!$D:$D=Z$6) * ('기록'!$F:$F<=2) * (IF($A$2=""전체"", TRUE, (YEAR('기록'!$A:$A)&"""")=$A$2)))) / Z$7, ""-""))"),"-") -> - | AA13: =IFERROR(__xludf.DUMMYFUNCTION("IF(AA$6="""", """", IFERROR(ROWS(FILTER('기록'!$F:$F, ('기록'!$D:$D=AA$6) * ('기록'!$F:$F<=2) * (IF($A$2=""전체"", TRUE, (YEAR('기록'!$A:$A)&"""")=$A$2)))) / AA$7, ""-""))"),"-") -> - | AB13: =IFERROR(__xludf.DUMMYFUNCTION("IF(AB$6="""", """", IFERROR(ROWS(FILTER('기록'!$F:$F, ('기록'!$D:$D=AB$6) * ('기록'!$F:$F<=2) * (IF($A$2=""전체"", TRUE, (YEAR('기록'!$A:$A)&"""")=$A$2)))) / AB$7, ""-""))"),"-") -> - | AC13: =IFERROR(__xludf.DUMMYFUNCTION("IF(AC$6="""", """", IFERROR(ROWS(FILTER('기록'!$F:$F, ('기록'!$D:$D=AC$6) * ('기록'!$F:$F<=2) * (IF($A$2=""전체"", TRUE, (YEAR('기록'!$A:$A)&"""")=$A$2)))) / AC$7, ""-""))"),0.2222222222222222) -> 0.22222222 | AD13: =IFERROR(__xludf.DUMMYFUNCTION("IF(AD$6="""", """", IFERROR(ROWS(FILTER('기록'!$F:$F, ('기록'!$D:$D=AD$6) * ('기록'!$F:$F<=2) * (IF($A$2=""전체"", TRUE, (YEAR('기록'!$A:$A)&"""")=$A$2)))) / AD$7, ""-""))"),"-") -> - | AE13: =IFERROR(__xludf.DUMMYFUNCTION("IF(AE$6="""", """", IFERROR(ROWS(FILTER('기록'!$F:$F, ('기록'!$D:$D=AE$6) * ('기록'!$F:$F<=2) * (IF($A$2=""전체"", TRUE, (YEAR('기록'!$A:$A)&"""")=$A$2)))) / AE$7, ""-""))"),"-") -> - | AF13: =IFERROR(__xludf.DUMMYFUNCTION("IF(AF$6="""", """", IFERROR(ROWS(FILTER('기록'!$F:$F, ('기록'!$D:$D=AF$6) * ('기록'!$F:$F<=2) * (IF($A$2=""전체"", TRUE, (YEAR('기록'!$A:$A)&"""")=$A$2)))) / AF$7, ""-""))"),"-") -> - | AG13: =IFERROR(__xludf.DUMMYFUNCTION("IF(AG$6="""", """", IFERROR(ROWS(FILTER('기록'!$F:$F, ('기록'!$D:$D=AG$6) * ('기록'!$F:$F<=2) * (IF($A$2=""전체"", TRUE, (YEAR('기록'!$A:$A)&"""")=$A$2)))) / AG$7, ""-""))"),0.5) -> 0.5 | AH13: =IFERROR(__xludf.DUMMYFUNCTION("IF(AH$6="""", """", IFERROR(ROWS(FILTER('기록'!$F:$F, ('기록'!$D:$D=AH$6) * ('기록'!$F:$F<=2) * (IF($A$2=""전체"", TRUE, (YEAR('기록'!$A:$A)&"""")=$A$2)))) / AH$7, ""-""))"),0.4166666666666667) -> 0.41666667 | AI13: =IFERROR(__xludf.DUMMYFUNCTION("IF(AI$6="""", """", IFERROR(ROWS(FILTER('기록'!$F:$F, ('기록'!$D:$D=AI$6) * ('기록'!$F:$F<=2) * (IF($A$2=""전체"", TRUE, (YEAR('기록'!$A:$A)&"""")=$A$2)))) / AI$7, ""-""))"),0.3333333333333333) -> 0.33333333
